Workbook
Name _Ａ: '別表4,5'!$D$31
Name _Ｂ: '別表4,5'!$D$32
Name _Ｃ: '別表4,5'!$D$33
Name _Ｄ: '別表4,5'!$D$34
Name _Ｅ: '別表4,5'!$D$36
Name _Ｆ: '別表4,5'!$D$37
Name _Ｇ: '別表4,5'!$D$38
Name _Ｈ: '別表4,5'!$D$39
Name _Hc: '別表4,5'!$G$39
Name _Hf: '別表4,5'!$J$39
Name _Hg: '別表4,5'!$K$39
Name _Ｉ: '別表4,5'!$D$40
Name _Ｊ: '別表4,5'!$D$41
Name _Ja: '別表4,5'!$E$41
Name _Jb: '別表4,5'!$F$41
Name _Jc: '別表4,5'!$G$41
Name _Jd: '別表4,5'!$H$41
Name _Je: '別表4,5'!$I$41
Name _Jf: '別表4,5'!$J$41
Name _Jg: '別表4,5'!$K$41
Name _Ｋ: '別表4,5'!$D$42
Name _Ｌ: '別表4,5'!$D$43
Name _Ｍ: '別表4,5'!$D$44
Name _Ma: '別表4,5'!$E$44
Name _Mb: '別表4,5'!$F$44
Name _Mc: '別表4,5'!$G$44
Name _Md: '別表4,5'!$H$44
Name _Me: '別表4,5'!$I$44
Name _Mf: '別表4,5'!$J$44
Name _Mg: '別表4,5'!$K$44
Name _Ｎ: '別表4,5'!$D$45
Name _Ｏ: '別表4,5'!$D$46
Name _P: '別表4,5'!$D$16
Name _PA: '別表4,5'!$D$7
Name _PB: '別表4,5'!$D$8
Name _PC: '別表4,5'!$D$9
Name _PD: '別表4,5'!$D$10
Name _PE: '別表4,5'!$D$11
Name _PF: '別表4,5'!$D$12
Name _PG: '別表4,5'!$D$13
Name _PH: '別表4,5'!$D$14
Name _PI: '別表4,5'!$D$15
Name _PP: '別表4,5'!$D$17
Name _Ｑ: '別表4,5'!$D$35
Name _V: '別表4,5'!$D$20
Name _W: '別表4,5'!$D$21
Name _Y: '別表4,5'!$D$24
Name _Z: '別表4,5'!$D$25
Name HKS: 販売量!$C$5
Name KYN: 販売量!$C$4

Sheet ナビ
B2: 料金算定ナビゲーター
B4: 案件名 | F4: 備考 | L4: ナビ | M4: 様式第１第1表 ガスの販売量 様式第１第2表 有形固定資産額
B5: 基本情報 | C5: 項目 | D5: 設定 | E5: 値 | F5: メモ | G5: 参照先1 | H5: 参照先2 | I5: 参照先3 | J5: インジケーター | M5: 様式第１第3表 営業項目別算定明細表
C6: 都道府県* | D6: 北海道 | E6: =_xlfn.XLOOKUP(D6,標準係数B!C:C,標準係数B!B:B, "IDなし", 0, 1) -> 1 | G6: 月平均販売量 | H6: 平均労務費 | I6: 産気率 | M6: 様式第１第4表 営業費以外の項目別算定明細表
C7: 法人税率* | D7: 0.22 | G7: 法人税係数 | M7: 様式第2 第1表 総括原価整理表
M8: 様式第2 第2表 機能別原価配分集計表 様式第2 第3表 需要種別原価整理表
M9: 様式第2 第4表 供給約款料金原価と料金収入の比較表
B10: 算定基礎 | C10: 項目 | D10: 設定 | E10: 値 | F10: メモ | G10: 参照先1 | H10: 参照先2 | I10: 参照先3 | J10: インジケーター | M10: 別表第４（第９条関係） 機能別原価配分式 別表第5（第10条関係） 需要種別への原価配分式
C11: 許可地点数* | D11: =SUM(D12:D13) -> 487 | G11: 車両の標準係数の抽出 | H11: 道路占用料の算出 | M11: 変更内容
C12: （共同住宅）* | D12: 0 | J12: =IF(D12=償却資産!D82,"","導管の内訳が一致しません。償却資産を確認してください。") | M12: レートメイク
C13: （単独住宅）* | D13: 487 | J13: =IF(D13=償却資産!D83,"","導管の内訳が一致しません。償却資産を確認してください。") | M13: 標準係数A 標準投資額
C14: 原料購入単価（円/Kg）* | D14: 106.05 | G14: 原料費 | M14: 標準係数B その他
C15: 固定資産税の減免措置* | D15: 有 | E15: =IF(D15="有",1,0) -> 1 | G15: 軽減係数の抽出 | M15: （参考）需要構成率
B19: ガイダンス | C19: 1.販売量 | D19: FALSE | E19: 様式第1_第1表で標準係数を採用するかどうかを選択→実数を採用する場合、販売量シートに入力。 ※供給約款以外の契約がある場合、標準係数は使えません。 | L19: FALSE | M19: 販売量設定は正しいか？
C20: 2.土地 | D20: FALSE | E20: 特定製造所用地を取得した場合は「土地」シートに入力する。土地がない場合、ブランクにする。 | L20: FALSE | M20: 販売量情報入力シートの需要家数は許可地点数と一致しているか？
C21: 3.償却資産 | D21: FALSE | E21: 標準係数または実績値を用い、償却資産の取得価額を入力する。 | L21: FALSE | M21: 土地情報は正しく入力されているか？
C22: 4.車両 | D22: FALSE | E22: 自社所有の車両がある場合、車両の取得時期を入力して標準係数を適用する。 | L22: FALSE | M22: 償却資産と許可地点数は一致しているか？
C23: 5.道路占用料 | D23: FALSE | E23: 地域ごとに設定されている道路占用料の区分を入力して標準係数を適用する。 | L23: FALSE | M23: 車両が自社所有の場合、取得時期は正しいか？
C24: 6.エラーチェック | D24: FALSE | L24: FALSE | M24: 道路占用料の区分は正しいか？
C25: 7.レートメイキング | D25: FALSE | L25: FALSE | M25: レートメイクの需要構成率は正しいか？
D26: FALSE | L26: FALSE | M26: レートメイクの収入ー総原価は0〜-1,000の範囲に収まっているか？
D27: FALSE | L27: FALSE | M27: 現行の料金表の入力はできているか？

Sheet 1_a
B2: 様式第１ （第３条、第４条、第５条、第６条、第７条関係） | I2: =ナビ!C4
B3: 第１表
B4: ガ ス の 販 売 量
B6: １供給地点当たり月平均販売量(a1) × 供給地点数(a2) × １２ = ガスの販売量(A)
B7: =IF(AND(KYN=1,HKS=1),VLOOKUP(ナビ!$E$6,標準係数B!$B$4:$G$50,3,FALSE),販売量!$P$11) -> 8.833 | E7: ㎥／月 | F7: =ナビ!$D$11 -> 487 | H7: =IF(AND(KYN=1,HKS=1),B7*F7*12,販売量!$O$11) -> 51621.887 | I7: ㎥／年 | K7: →販売量シートへ
B9: 第２表
B10: 有形固定資産投資額
E12: 特定製造所別 | F12: １ | G12: ２ | H12: 計 | I12: 備考 | K12: →土地シートへ
B13: 土 | C13: 項 目
C14: 取 得 年 月 日 | F14: =IF(COUNT(土地!$D$5:$D$14) = 1,土地!$D$5, "複数土地") -> 32153
C15: 取得面積 | E15: (b1) | F15: =土地!E15 -> 649.1 | H15: =IF(F15="","",F15+G15) -> 649.1
C16: 取得価額 | E16: (b2) | F16: =土地!F15 -> 15300000 | H16: =IF(F16="","",F16+G16) -> 15300000
B17: 地 | C17: 1㎡当り取得価額 (b2/b1) (b3) | F17: =IF(F15="","",IF(F15>0,ROUND(F16/F15,0),0)) -> 23571 | G17: =IF(G15="","",IF(G15>0,ROUND(G16/G15,0),0)) | H17: =IF(H15="","",ROUND(H16/H15,0)) -> 23571
C18: 所要面積 | E18: (b4) | F18: =IF(COUNT(土地!$M$5:M14) = 1,土地!$M$5, "複数土地") -> 295
C19: 土地投資額 | E19: (b3×ｂ4) | F19: =土地!N15 -> 6953445 | G19: =IF(G15>0,IF(G15=G18,G16,ROUND(G17*G18,0)),"") | H19: =土地!N15 -> 6953445
B21: 建 物 及 び 償 却 資 産 | E21: 投資額内訳 | F21: １供給地点 当たり投資額 （円） | G21: 供給地点数 | H21: 投 資 額① （円） | I21: 投 資 額② （円） | K21: →償却資産シートへ
C22: 項 目
C23: 建 物 | F23: =IFERROR(ROUND(H23/G23,0), "") -> 11023 | G23: =償却資産!D78 -> 487 | H23: =償却資産!E78 -> 5368245 | I23: -
C24: 構 築 物 | F24: =IFERROR(ROUND(H24/G24,0), "") -> 2630 | G24: =償却資産!D79 -> 487 | H24: =償却資産!E79 -> 1280740 | I24: -
C25: 集 合 装 置 | F25: =IFERROR(ROUND((H25+I25)/G25,0), "") -> 7301 | G25: =償却資産!D80 -> 487 | H25: =償却資産!E80 -> 0 | I25: =償却資産!F80 -> 3555750
C26: 容 器 | F26: =IFERROR(ROUND(H26/G26,0), "") | G26: =償却資産!D81 -> 0 | H26: =償却資産!E81 -> 0 | I26: -
C27: 導 | D27: 共同 住宅 | E27: 導管取替(B④) | G27: 0 | H27: - | I27: -
E28: 上記以外 | F28: =IFERROR(ROUND((H28+I28)/G28,0), "") | G28: =償却資産!D82 -> 0 | H28: =償却資産!E82 -> 0 | I28: =償却資産!F82 -> 0
C29: 管 | D29: 単独 住宅 | E29: 導管取替(B⑤) | G29: 0 | H29: - | I29: -
E30: 上記以外 | F30: =IFERROR(ROUND((H30+I30)/G30,0), "") -> 75594 | G30: =償却資産!D83 -> 487 | H30: =償却資産!E83 -> 0 | I30: =償却資産!F83 -> 36814400
C31: メ ー タ ー | F31: =IFERROR(ROUND(H31/G31,0), "") -> 11010 | G31: =償却資産!D84 -> 487 | H31: =償却資産!E84 -> 5361870 | I31: -
C32: 備 品 | F32: =IFERROR(ROUND(H32/G32,0), "") | G32: =償却資産!D85 -> 0 | H32: =償却資産!E85 -> 0 | I32: -
C33: 車 両(B⑥) | F33: =IFERROR(ROUND(H33/G33,0), "") -> 0 | G33: =ナビ!D11 -> 487 | H33: =車両!K10 -> 0 | I33: -
C34: 投資額①計 (B②) | H34: =SUM(H23:H33) -> 12010855 | I34: -
C35: 投資額②計 (B③) | H35: - | I35: =SUM(I23:I34) -> 40370150
C36: 小 計 B⑦(＝B②＋B③) | I36: =H34+I35 -> 52381005
B37: 合 計 B (＝B①＋B⑦) | I37: =SUM(H19,I36) -> 59334450

Sheet 1_b
B2: 第３表 | I2: =ナビ!C4
B3: 営業費項目別算定明細表
B5: (1)原料費
B6: ガスの販売量(A) ÷ 産気率(c1) ＝ 原料の数量(c2)
B7: ='1_a'!H7 -> 51621.887 | C7: ㎥/年 | D7: =VLOOKUP(ナビ!E6,標準係数B!B4:G50,6,FALSE) -> 0.476 | F7: ㎥/kg | G7: =ROUND(B7/D7,2) -> 108449.34 | H7: kg/年
B9: 原料購入単価(c3) × 原料の数量(c2) ＝ 原料費(C）
B10: =ナビ!D14 -> 106.05 | C10: 円/kg | D10: =G7 -> 108449.34 | F10: kg/年 | G10: =ROUNDDOWN(B10*D10,0) -> 11501052 | H10: 円
B12: (2)労務費 | K12: 労務費算定基礎
B13: １供給地点当たり所要人数(d1) × 供給地点数(d2) ＝ 所要人員数(d3) | K13: 導管の種類 | L13: 標準係数 | M13: 地点数 | N13: 所要人員数
B14: =ROUND(G14/D14,5) -> 0.0031 | C14: 人 | D14: =ナビ!D11 -> 487 | G14: =N16 -> 1.5097 | H14: 人 | K14: 鋼管 | L14: =標準係数B!K4 -> 0.0032 | M14: =償却資産!D64+償却資産!D66 -> 0 | N14: =L14*M14 -> 0
K15: PE管 | L15: =標準係数B!K5 -> 0.0031 | M15: =償却資産!D65+償却資産!D67 -> 487 | N15: =L15*M15 -> 1.5097
B16: １人当たり年間平均労務費(d4) × 所要人員数(d3) ＝ 労務費(D) | K16: 合計 | M16: =SUM(M14:M15) -> 487 | N16: =SUM(N14:N15) -> 1.5097
B17: =VLOOKUP(ナビ!E6,標準係数B!B4:G50,4,FALSE) -> 5683000 | C17: 円 | D17: =G14 -> 1.5097 | G17: =ROUND(B17*D17,0) -> 8579625 | H17: 円 | M17: =IF(M16=ナビ!D11,"","導管地点数エラー")
B19: (3)修繕費
B20: 建物及び償却資産投資額(B⑦-B④-B⑤) × 修繕費率(e1) ＝ 修繕費(E①)
B21: ='1_a'!I36 -> 52381005 | C21: 円 | D21: =G21/B21 -> 0.030000035 | G21: =償却資産!Q56+車両!K12 -> 1571432 | H21: 円
B23: 導管取替に係る投資額(B④+B⑤) × 修繕費率(e2) ＝ 修繕費(E②)
C24: 円 | D24: =IF(B24=0,"－",ROUND(G24/B24,5)) -> － | G24: 0 | H24: 円
B26: 修繕費（Ｅ） (E①+E②) | G26: =SUM(G21,G24) -> 1571432 | H26: 円
I29: =ナビ!C4
B30: (4)租税課金
B31: （固定資産税）
B32: 〔土地〕
B33: 標準所要面積の範囲内の面積 に係る固定資産税評価額(f1) | D33: × 地方税法に定める標準税率(f2)＝土地に係る固定資産税額(F①)
B34: =ROUND(土地!O15,0) -> 2784210 | C34: 円 | D34: =IF(B34>=0,標準係数B!K9,"－") -> 0.017 | G34: =ROUND(B34*D34,0) -> 47332 | H34: 円
B35: 〔建物及び償却資産〕
B36: 建物及び償却資産 投資額(B②×1/2） | C36: + | D36: (B③ × 軽減係数(f3) × 1/2) ＝ | G36: 建物及び償却資産に 係る課税標準額(f4)
B37: ='1_a'!H34 -> 12010855 | C37: 円 | D37: ='1_a'!I35 -> 40370150 | E37: 円 | F37: =IF(ナビ!E15=0,標準係数B!K12,標準係数B!K11) -> 0.46 | G37: =ROUND(B37/2+D37*F37/2,0) -> 15290562 | H37: 円
B39: 建物及び償却資産に 係る課税標準額(f4) | C39: × 地方税法に定める標準税率(f2) ＝ | G39: 建物及び償却資産に 係る固定資産税(F②)
B40: =G37 -> 15290562 | C40: 円 | D40: =標準係数B!K10 -> 0.014 | G40: =ROUND(B40*D40,0) -> 214068 | H40: 円
B42: 固定資産税(F) (F①+F②) | G42: =G34+G40 -> 261400 | H42: 円
B44: （事業税）
B45: 事業報酬額(L) × | C45: 事業報酬額中の自己 資本相当分比率(g1) | E45: × 事業税率(g2)/（1-事業税率）＝ 事業税(G)
B46: ='1_c'!G25 -> 1613897 | C46: 円 | D46: =標準係数B!K15 -> 0.35 | E46: =標準係数B!K13/(1-標準係数B!K13) -> 0.0090817356 | G46: =ROUND(B46*D46*E46,0) -> 5130 | H46: 円
B48: （道路占用料）
B49: １供給地点当たりの占用料(h1) × 供給地点数(h2) ＝ 道路占用料(H)
B50: =G50/D50 -> 700 | C50: 円 | D50: =SUM(ナビ!D11) -> 487 | G50: =SUM(道路占用料!E8) -> 340900 | H50: 円
B52: (5)減価償却費
B53: 建物及び償却資産(車両を除く。)投資額(B⑦-B⑥) × 償却率(i1) ＝ 減価償却費(I①)
B54: ='1_a'!I36-'1_a'!H33 -> 52381005 | C54: 円 | D54: =G54/B54 -> 0.074306879 | G54: =ROUND(償却資産!S56,0) -> 3892269 | H54: 円
...

Sheet 1_c
B2: 第４表 | H2: =ナビ!C4
B4: 営業費以外の項目算定明細表
B6: （法人税）
B7: 事業報酬額(L) × | D7: 事業報酬額中の自己 資本相当分比率(k1) | F7: × 法人税係数(k2) ＝ 法人税(K①)
B8: =G25 -> 1613897 | C8: 円 | D8: =標準係数B!K15 -> 0.35 | F8: =ROUND(ナビ!D7/(1-(ナビ!D7+ナビ!D7*(標準係数B!K31+標準係数B!K32+標準係数B!K35))),4) -> 0.2965 | G8: =ROUND(B8*D8*F8,0) -> 167482 | H8: 円
B10: （地方法人税）
B11: 法人税(K①) × | D11: 地方法人税法に定める税率(k3) | G11: ＝ 地方法人税(K②)
B12: =G8 -> 167482 | C12: 円 | D12: =標準係数B!K35 -> 0.103 | G12: =ROUND(B12*D12,0) -> 17251 | H12: 円
B14: （住民税（法人税割に限る。））
B15: 法人税(K①) × | D15: 地方税法に定める標準税率(k4) | G15: ＝ 住民税(K③)
B16: =G8 -> 167482 | C16: 円 | D16: =標準係数B!K31+標準係数B!K32 -> 0.07 | G16: =IF(B16=0,0,ROUND(B16*D16,0)) -> 11724 | H16: 円
B18: 法人税及び地方法人税並びに住民税(K) (K①+K②+K③) | G18: =G8+G12+G16 -> 196457 | H18: 円
B20: 第５表
B22: 事業報酬算定明細表
B24: 有形固定資産投資額(B) × 標準報酬率(l1) ＝ 事業報酬額(L)
B25: ='1_a'!I37 -> 59334450 | C25: 円 | D25: =標準係数B!K8 -> 0.0272 | G25: =ROUND(B25*D25,0) -> 1613897 | H25: 円

Sheet 2_a
B2: 様式第２ （第８条、第９条、第１０条、第１１条関係） | H2: =ナビ!C4
B3: 第１表
B5: 総 原 価 整 理 表
B8: 項目 | E8: 金額(円) | F8: 構成比(%)
C9: 原料費 | E9: ='1_b'!G10 -> 11501052 | G9: =E9/E$22*100 -> 36.071361 | P9: 原料費 | Q9: =G9/100 -> 0.36071361
C10: 労務費 | E10: ='1_b'!G17 -> 8579625 | G10: =E10/E$22*100 -> 26.908734 | P10: 労務費 | Q10: =G10/100 -> 0.26908734
B11: 個別原価項目 | C11: 修繕費 | E11: ='1_b'!G26 -> 1571432 | G11: =E11/E$22*100 -> 4.9285658 | P11: 修繕費 | Q11: =G11/100 -> 0.049285658
C12: 租税課金 | D12: 固定資産税 | E12: ='1_b'!G42 -> 261400 | G12: =E12/E$22*100 -> 0.81984273 | P12: 租税課金 | Q12: =SUM(G12:G14)/100 -> 0.01905115
D13: 事業税 | E13: ='1_b'!G46 -> 5130 | G13: =E13/E$22*100 -> 0.016089492 | P13: 減価償却費 | Q13: =G15/100 -> 0.1220753
D14: 道路占用料 | E14: ='1_b'!G50 -> 340900 | G14: =E14/E$22*100 -> 1.0691828 | P14: その他経費 | Q14: =G16/100 -> 0.12300784
C15: 減価償却費 | E15: ='1_b'!G59 -> 3892269 | G15: =E15/E$22*100 -> 12.20753 | P15: 事業報酬額 | Q15: =G18/100 -> 0.05061751
C16: その他経費 | E16: ='1_b'!G63 -> 3922002 | G16: =E16/E$22*100 -> 12.300784 | P16: 法人税等 | Q16: =SUM(G19:G21)/100 -> 0.0061615854
C17: 小計 | E17: =SUM(E9:E16) -> 30073810 | G17: =E17/E$22*100 -> 94.32209
C18: 事業報酬額 | E18: ='1_c'!G25 -> 1613897 | G18: =E18/E$22*100 -> 5.061751
C19: 法人税及 び地方法人税並びに 住民税 | D19: 法人税 | E19: ='1_c'!G8 -> 167482 | G19: =E19/E$22*100 -> 0.52528271
D20: 地方法人税 | E20: ='1_c'!G12 -> 17251 | G20: =E20/E$22*100 -> 0.054105229
D21: 住民税 （法人税割に限る。） | E21: ='1_c'!G16 -> 11724 | G21: =E21/E$22*100 -> 0.036770605
B22: 合計（総原価） | E22: =SUM(E17:E21) -> 31884164 | G22: =E22/E$22*100 -> 100
B24: ガスの販売量 | E24: ='1_a'!H7 -> 51621.887 | F24: ㎥／年
B25: １㎥当たり単価 | E25: =ROUND(E22/E24,2) -> 617.65 | F25: 円

Sheet 2_b
B2: 第２表 | G2: =ナビ!C4
B3: 機能別原価配分集計表
G4: （単位：円）
B5: 項 目 | C5: 製造需要原価 | E5: 供給需要原価 | G5: 需要家原価
C6: 固定費 | D6: 変動費 | E6: 固定費 | F6: 変動費
B7: 原 料 費 | D7: ='別表4,5'!F31 -> 11501052 | Q7: 製造需要原価（固定） | R7: =C17 -> 2281788
B8: 労 務 費 | E8: ='別表4,5'!H32 -> 3482470 | G8: ='別表4,5'!K32 -> 5097155 | Q8: 製造需要原価（変動） | R8: =D17 -> 12781377
B9: 修 繕 費 | C9: ='別表4,5'!E33 -> 306142 | E9: ='別表4,5'!H33 -> 921097 | G9: ='別表4,5'!K33 -> 344193 | Q9: 供給需要原価（固定） | R9: =E17 -> 8647304
B10: 固 定 資 産 税 | C10: ='別表4,5'!E34 -> 75591 | E10: ='別表4,5'!H34 -> 135264 | G10: ='別表4,5'!K34 -> 50545 | Q10: 供給需要原価（変動） | R10: =F17 -> 526327
B11: 道路占用料 | E11: ='別表4,5'!H35 -> 340900 | Q11: 需要家原価 | R11: =G17 -> 7647368
B12: 減 価 償 却 費 | C12: ='別表4,5'!E38 -> 758282 | E12: ='別表4,5'!H38 -> 2281460 | G12: ='別表4,5'!K38 -> 852527
B13: そ の 他 経 費 | C13: ='別表4,5'!E40 -> 1062103 | D13: ='別表4,5'!F40 -> 834058 | E13: ='別表4,5'!H40 -> 601683 | F13: ='別表4,5'!I40 -> 472495 | G13: ='別表4,5'!K40 -> 951663
B14: 事 業 報 酬 額 | C14: ='別表4,5'!E42 -> 70697 | D14: ='別表4,5'!F42 -> 396006 | E14: ='別表4,5'!H42 -> 787213 | F14: ='別表4,5'!I42 -> 47914 | G14: ='別表4,5'!K42 -> 312067
B15: 法人税・地方法人税・住民税 （法人税割に限る。） | C15: ='別表4,5'!E43 -> 8606 | D15: ='別表4,5'!F43 -> 48205 | E15: ='別表4,5'!H43 -> 95826 | F15: ='別表4,5'!I43 -> 5833 | G15: ='別表4,5'!K43 -> 37987
B16: 事 業 税 | C16: ='別表4,5'!E45 -> 367 | D16: ='別表4,5'!F45 -> 2056 | E16: ='別表4,5'!H45 -> 1391 | F16: ='別表4,5'!I45 -> 85 | G16: ='別表4,5'!K45 -> 1231
B17: 合 計 | C17: =SUM(C7:C16) -> 2281788 | D17: =SUM(D7:D16) -> 12781377 | E17: =SUM(E7:E16) -> 8647304 | F17: =SUM(F7:F16) -> 526327 | G17: =SUM(G7:G16) -> 7647368
B19: 第３表
B20: 需要種別原価整理表
B22: 機 能 別 原 価 | D22: 配 分 基 準 | F22: 原 単 位 | Q22: 供給約款 | R22: =B29 -> 30715365
B23: 変 動 費 計 | D23: 年 間 販 売 量 比 | F23: ='別表4,5'!G52 -> 257.79 | G23: 円／㎥ | Q23: 非規制料金 | R23: =D29 -> 0
B24: 製造需要原価固定費 | D24: ピーク月販売量比 | F24: ='別表4,5'!G53 -> 341.13 | G24: 円／㎥ | Q24: 特定大口 | R24: =F29 -> 1168799
B25: 供給需要原価固定費 | D25: 延メーター通過量比 | F25: ='別表4,5'!G54 -> 591.87 | G25: 円／㎥
B26: 需 要 家 原 価 | D26: 延供給地点数比 | F26: ='別表4,5'!G55 -> 1308.58 | G26: 円／地点
B28: 供給約款料金原価（円） | D28: 非規制需要料金原価（円） | F28: 旧特定ガス大口供給料金原価（円）
B29: ='別表4,5'!I56 -> 30715365 | D29: ='別表4,5'!K56 -> 0 | F29: ='別表4,5'!M56 -> 1168799

Sheet 2_c
B2: 第４表 | E2: =ナビ!C4
B4: 供給約款料金原価と料金収入の比較表
B7: 供給約款料金原価（ａ） （円） | C7: ガスの販売量（ｂ） （㎥） | D7: 平均単価（ａ／ｂ） （円／㎥） | E7: 想定料金収入 （円）
B8: ='2_b'!B29 -> 30715365 | C8: =IF(HKS=1,'1_a'!H7,販売量!O8) -> 48604.487 | D8: =B8/C8 -> 631.94506 | E8: =レートメイク!E29 -> 30715365

Sheet 別表4,5
M1: =ナビ!C4
B2: 別表第４（第９条関係）
B3: 機能別原価配分式
B5: 有形固定資産投資額
B6: 建物及び償却資産 | C6: 記号 | D6: 投資額
B7: 土地 | C7: PA | D7: ='1_a'!H19 -> 6953445
B8: 建物 | C8: PB | D8: =SUM('1_a'!H23:I23) -> 5368245
B9: 構築物 | C9: PC | D9: =SUM('1_a'!H24:I24) -> 1280740
B10: 集合装置 | C10: PD | D10: =SUM('1_a'!H25:I25) -> 3555750
B11: 容器 | C11: PE | D11: =SUM('1_a'!H26:I26) -> 0
B12: 導管 | C12: PF | D12: =SUM('1_a'!H27:I30) -> 36814400
B13: メーター | C13: PG | D13: =SUM('1_a'!H31:I31) -> 5361870
B14: 備品 | C14: PH | D14: =SUM('1_a'!H32:I32) -> 0
B15: 車両 | C15: PI | D15: =SUM('1_a'!H33:I33) -> 0
B16: 合計 | C16: P | D16: =SUM(D7:D15) -> 59334450
B17: （車両を除く合計） | C17: PP | D17: =SUM(D7:D14) -> 59334450
B19: （導管配分比率）
B20: 供給需要原価（本支管） | C20: V | D20: =標準係数B!AH6 -> 0.834
B21: 需要家原価（供給管分） | C21: W | D21: =標準係数B!AH7 -> 0.166
B23: （労務費及び車両配分比率）
B24: 供給需要家原価 | C24: Y | D24: =標準係数B!AH4 -> 0.4059
B25: 需要家原価 | C25: Z | D25: =標準係数B!AH5 -> 0.5941
M27: =ナビ!C4
B28: 機能別原価配分式
B29: 項目 | C29: 総原価 | E29: 製造需要原価 | H29: 供給需要原価 | K29: 需要家原価
E30: 固定費ａ | F30: 変動費ｂ | G30: 計ｃ | H30: 固定費ｄ | I30: 変動費ｅ | J30: 計ｆ | K30: ｇ
B31: 原料費 | C31: Ａ | D31: ='2_a'!E9 -> 11501052 | F31: =ROUND(_Ａ,0) -> 11501052 | G31: =SUM(E31:F31) -> 11501052 | K31: =D31-G31-J31 -> 0
B32: 労務費 | C32: Ｂ | D32: ='2_a'!E10 -> 8579625 | H32: =ROUND(_Ｂ*_Y,0) -> 3482470 | J32: =SUM(H32:I32) -> 3482470 | K32: =D32-G32-J32 -> 5097155
B33: 修繕費 | C33: Ｃ | D33: ='2_a'!E11 -> 1571432 | E33: =ROUND((_PB+_PC+_PD+_PE)/(_P-_PA)*_Ｃ,0) -> 306142 | G33: =SUM(E33:F33) -> 306142 | H33: =ROUND((_V*_PF+_PH+_Y*_PI)/(_P-_PA)*_Ｃ,0) -> 921097 | J33: =SUM(H33:I33) -> 921097 | K33: =D33-G33-J33 -> 344193
B34: 固定資産税 | C34: Ｄ | D34: ='2_a'!E12 -> 261400 | E34: =ROUND((_PA+_PB+_PC+_PD+_PE)/_P*_Ｄ,0) -> 75591 | G34: =SUM(E34:F34) -> 75591 | H34: =ROUND((_V*_PF+_PH+_Y*_PI)/_P*_Ｄ,0) -> 135264 | J34: =SUM(H34:I34) -> 135264 | K34: =D34-G34-J34 -> 50545
B35: 道路占用料 | C35: Ｑ | D35: ='2_a'!E14 -> 340900 | H35: =ROUND(_Ｑ,0) -> 340900 | J35: =SUM(H35:I35) -> 340900 | K35: =D35-G35-J35 -> 0
B36: 減価償却費（車両分除く） | C36: Ｅ | D36: ='1_b'!G54 -> 3892269 | E36: =ROUND((_PB+_PC+_PD+_PE)/(_PP-_PA)*_Ｅ,0) -> 758282 | G36: =SUM(E36:F36) -> 758282 | H36: =ROUND((_V*_PF+_PH)/(_PP-_PA)*_Ｅ,0) -> 2281460 | J36: =SUM(H36:I36) -> 2281460 | K36: =D36-G36-J36 -> 852527
B37: 減価償却費（車両分） | C37: Ｆ | D37: ='1_b'!G57 -> 0 | H37: =ROUND(_Ｆ*_Y,0) -> 0 | J37: =SUM(H37:I37) -> 0 | K37: =D37-G37-J37 -> 0
B38: 減価償却費 | C38: Ｇ | D38: =SUM(D36:D37) -> 3892269 | E38: =SUM(E36:E37) -> 758282 | G38: =SUM(G36:G37) -> 758282 | H38: =SUM(H36:H37) -> 2281460 | J38: =SUM(J36:J37) -> 2281460 | K38: =D38-G38-J38 -> 852527
B39: 小計① | C39: Ｈ | D39: =SUM(D31:D35,D38) -> 26146678 | E39: =SUM(E31:E35,E38) -> 1140015 | F39: =SUM(F31:F35,F38) -> 11501052 | G39: =SUM(G31:G35,G38) -> 12641067 | H39: =SUM(H31:H35,H38) -> 7161191 | I39: =SUM(I31:I35,I38) -> 0 | J39: =SUM(J31:J35,J38) -> 7161191 | K39: =D39-G39-J39 -> 6344420
B40: その他経費 | C40: Ｉ | D40: ='2_a'!E16 -> 3922002 | E40: =ROUND(_Hc/_Ｈ*(_Ｂ+_Ｃ+_Ｄ+_Ｑ+_Ｇ)/_Ｈ*_Ｉ,0) -> 1062103 | F40: =ROUND(_Hc/_Ｈ*_Ａ/_Ｈ*_Ｉ,0) -> 834058 | G40: =SUM(E40:F40) -> 1896161 | H40: =ROUND(_Hf/_Ｈ*(_Ｂ+_Ｃ+_Ｄ+_Ｑ+_Ｇ)/_Ｈ*_Ｉ,0) -> 601683 | I40: =ROUND(_Hf/_Ｈ*_Ａ/_Ｈ*_Ｉ,0) -> 472495 | J40: =SUM(H40:I40) -> 1074178 | K40: =D40-G40-J40 -> 951663
B41: 小計② | C41: Ｊ | D41: =SUM(D39:D40) -> 30068680 | E41: =SUM(E39:E40) -> 2202118 | F41: =SUM(F39:F40) -> 12335110 | G41: =SUM(G39:G40) -> 14537228 | H41: =SUM(H39:H40) -> 7762874 | I41: =SUM(I39:I40) -> 472495 | J41: =SUM(J39:J40) -> 8235369 | K41: =D41-G41-J41 -> 7296083
B42: 事業報酬額 | C42: Ｋ | D42: ='2_a'!E18 -> 1613897 | E42: =ROUND((_PA+_PB+_PC+_PD+_PE)/_P*_Ｋ*_Ja/_Jc,0) -> 70697 | F42: =ROUND((_PA+_PB+_PC+_PD+_PE)/_P*_Ｋ*_Jb/_Jc,0) -> 396006 | G42: =SUM(E42:F42) -> 466703 | H42: =ROUND((_V*_PF+_PH+_Y*_PI)/_P*_Ｋ*_Jd/_Jf,0) -> 787213 | I42: =ROUND((_V*_PF+_PH+_Y*_PI)/_P*_Ｋ*_Je/_Jf,0) -> 47914 | J42: =SUM(H42:I42) -> 835127 | K42: =D42-G42-J42 -> 312067
B43: 法人税 | C43: Ｌ | D43: =SUM('2_a'!E19:E21) -> 196457 | E43: =ROUND((_PA+_PB+_PC+_PD+_PE)/_P*_Ｌ*_Ja/_Jc,0) -> 8606 | F43: =ROUND((_PA+_PB+_PC+_PD+_PE)/_P*_Ｌ*_Jb/_Jc,0) -> 48205 | G43: =SUM(E43:F43) -> 56811 | H43: =ROUND((_V*_PF+_PH+_Y*_PI)/_P*_Ｌ*_Jd/_Jf,0) -> 95826 | I43: =ROUND((_V*_PF+_PH+_Y*_PI)/_P*_Ｌ*_Je/_Jf,0) -> 5833 | J43: =SUM(H43:I43) -> 101659 | K43: =D43-G43-J43 -> 37987
B44: 小計③ | C44: Ｍ | D44: =SUM(D41:D43) -> 31879034 | E44: =SUM(E41:E43) -> 2281421 | F44: =SUM(F41:F43) -> 12779321 | G44: =SUM(G41:G43) -> 15060742 | H44: =SUM(H41:H43) -> 8645913 | I44: =SUM(I41:I43) -> 526242 | J44: =SUM(J41:J43) -> 9172155 | K44: =D44-G44-J44 -> 7646137
...

Sheet 変更内容
F2: 実 施 の 内 容 | I2: =ナビ!C4
I4: （単位：円）
B5: 項目 | C5: 区分 | F5: 新 | H5: 旧
F6: 基本料金 | G6: 基準単位料金 | H6: 基本料金 | I6: 調整単位料金
B7: Ａ群 | C7: 0㎥から | E7: =レートメイク!D20 -> 8 | F7: =レートメイク!E20 -> 1200 | G7: =レートメイク!F20 -> 550 | H7: =レートメイク!L20 -> 1080 | I7: =レートメイク!M20 -> 493.04
B8: Ｂ群 | C8: =レートメイク!C21 -> 8.1 | E8: =レートメイク!D21 -> 30 | F8: =レートメイク!E21 -> 1800 | G8: =レートメイク!F21 -> 475 | H8: =レートメイク!L21 -> 1680 | I8: =レートメイク!M21 -> 418.04
B9: Ｃ群 | C9: =レートメイク!C22 -> 30.1 | F9: =レートメイク!E22 -> 4050 | G9: =レートメイク!F22 -> 400 | H9: =レートメイク!L22 -> 3930 | I9: =レートメイク!M22 -> 343.04
B12: 供給 約款 料金 の 平均 単価 | C12: 新 | E12: (届出）供給約款料金原価
E13: 原価（原資）算定期間中の供給約款ガス販売量
D14: ='2_b'!B29 -> 30715365 | F14: ÷ | G14: =IF(HKS=1,'1_a'!H7,販売量!O8) -> 48604.487 | H14: ＝ | I14: =+ROUND(+D14/G14,2) -> 631.95
C15: 旧 | E15: （届出）供給約款料金の変更前料金収入（※）
E16: 原価（原資）算定期間中の供給約款ガス販売量
D17: =I41 -> 27251333 | F17: ÷ | G17: =G14 -> 48604.487 | H17: ＝ | I17: =IF(D17="","",+ROUND(+D17/G17,2)) -> 560.68
E18: (新)平均単価 | F18: × 100 | G18: － 100
B19: 改定率 | E19: (旧)平均単価
B20: (ﾊﾟｰｾﾝﾄ) | D20: ・供給約款 | F20: =I14 -> 631.95 | G20: × 100 － 100 | H20: ＝ | I20: =IF(F21="","",ROUND(((F20/F21*100-100)/100),4)) -> 0.1271
F21: =I17 -> 560.68
B24: （※）変更前料金収入
C25: 料金種別ごとに以下の式により算定された額の合計額とする。
C26: 基本料金［変更前］×原価（原資）算定期間中の延調定件数その他需要想定＋
C27: ＋従量料金単価［変更前］×原価（原資）算定期間中のガス販売量
C28: 使用量区画別料金の場合
D29: 料金種別ごとに以下の式により算定された額の合計額とする。
D30: 最低使用量料金［変更前］×原価（原資）算定期間中の延調定件数
D31: ＋区画別使用量料金単価［変更前］×原価（原資）算定期間中のガス販売量
D32: －最低使用量×延調定件数
B33: 供給約款変更前料金収入 | C33: 基本料金 | E33: 金額 | F33: × | G33: 年間延調定数 | H33: ＝ | I33: 基本料金収入額
D34: Ａ群 | E34: =レートメイク!L20 -> 1080 | F34: × | G34: =レートメイク!E11 -> 4927 | H34: ＝ | I34: =IF(E34="","",ROUND(+E34*G34,0)) -> 5321160
D35: Ｂ群 | E35: =レートメイク!L21 -> 1680 | F35: × | G35: =レートメイク!E12 -> 753 | H35: ＝ | I35: =IF(E35="","",ROUND(+E35*G35,0)) -> 1265040
D36: Ｃ群 | E36: =レートメイク!L22 -> 3930 | F36: × | G36: =レートメイク!E13 -> 116 | H36: ＝ | I36: =IF(E36="","",ROUND(+E36*G36,0)) -> 455880
C37: 調整単位料金 | E37: 金額 | F37: × | G37: 年間販売量 | H37: ＝ | I37: 単位料金収入額
D38: Ａ群 | E38: =レートメイク!M20 -> 493.04 | F38: × | G38: =レートメイク!F11 -> 16525.487 | H38: ＝ | I38: =IF(E38="","",ROUND(+E38*G38,0)) -> 8147726
D39: Ｂ群 | E39: =レートメイク!M21 -> 418.04 | F39: × | G39: =レートメイク!F12 -> 14095.3 | H39: ＝ | I39: =IF(E39="","",ROUND(+E39*G39,0)) -> 5892399
D40: Ｃ群 | E40: =レートメイク!M22 -> 343.04 | F40: × | G40: =レートメイク!F13 -> 17983.7 | H40: ＝ | I40: =IF(E40="","",ROUND(+E40*G40,0)) -> 6169128
E41: 合 | G41: 計 | I41: =SUM(I34:I40) -> 27251333

Sheet レートメイク
G1: =ナビ!C4
B2: レートメイク
B4: 総原価 | D4: ='2_b'!B29 -> 30715365
B5: 年間延べ調定数 | D5: =IF(HKS=1,'1_a'!F7*12,販売量!R8) -> 5796
B6: 販売量 | D6: =IF(HKS=1,'1_a'!H7,販売量!O8) -> 48604.487
B7: 単位販売量 | D7: =D6/D5 -> 8.3858673
B9: 需要構成率 | E9: 想定需要
B10: 需要群名 | C10: 延調定数比率 | D10: 年間販売量比率 | E10: 年間調定数 | F10: 年間販売量
B11: A群 | C11: 0.85 | D11: 0.34 | E11: =D5-SUM(E12:E13) -> 4927 | F11: =D6-SUM(F12:F13) -> 16525.487
B12: B群 | C12: 0.13 | D12: 0.29 | E12: =ROUND($D$5*C12,0) -> 753 | F12: =ROUND($D$6*D12,1) -> 14095.3
B13: C群 | C13: 0.02 | D13: 0.37 | E13: =ROUND($D$5*C13,0) -> 116 | F13: =ROUND($D$6*D13,1) -> 17983.7
E14: =SUM(E11:E13) -> 5796 | F14: =SUM(F11:F13) -> 48604.487
B17: 新料金表 | I17: 旧料金表
C19: MIN | D19: MAX | E19: 基本 | F19: 基準単位 | J19: MIN | K19: MAX | L19: 基本 | M19: 調整単位
B20: A | C20: 0 | D20: 8 | E20: 1200 | F20: 550 | I20: A | J20: 0 | K20: 8 | L20: 1080 | M20: 493.04
B21: B | C21: =D20+0.1 -> 8.1 | D21: 30 | E21: =E20+D20*F20-D20*F21 -> 1800 | F21: 475 | I21: B | J21: =K20+0.1 -> 8.1 | K21: 30 | L21: =L20+K20*M20-K20*M21 -> 1680 | M21: 418.04
B22: C | C22: =D21+0.1 -> 30.1 | D22: 999999 | E22: =E21+D21*F21-D21*F22 -> 4050 | F22: 400 | I22: C | J22: =K21+0.1 -> 30.1 | K22: 999999 | L22: =L21+K21*M21-K21*M22 -> 3930 | M22: 343.04
B24: 想定収入 | I24: 想定収入
B25: 需要群名 | C25: 基本料金 | D25: 従量料金 | E25: 合計 | I25: 需要群名 | J25: 基本料金 | K25: 従量料金 | L25: 合計
B26: A群 | C26: =E11*E20 -> 5912400 | D26: =F11*F20 -> 9089017.6 | E26: =SUM(C26:D26) -> 15001418 | I26: A群 | J26: =E11*L20 -> 5321160 | K26: =F11*M20 -> 8147725.9 | L26: =SUM(J26:K26) -> 13468886
B27: B群 | C27: =E12*E21 -> 1355400 | D27: =F12*F21 -> 6695267.5 | E27: =SUM(C27:D27) -> 8050667.5 | I27: B群 | J27: =E12*L21 -> 1265040 | K27: =F12*M21 -> 5892399.2 | L27: =SUM(J27:K27) -> 7157439.2
B28: C群 | C28: =E13*E22 -> 469800 | D28: =F13*F22 -> 7193480 | E28: =SUM(C28:D28) -> 7663280 | I28: C群 | J28: =E13*L22 -> 455880 | K28: =F13*M22 -> 6169128.4 | L28: =SUM(J28:K28) -> 6625008.4
B29: 合計 | C29: =SUM(C26:C28) -> 7737600 | D29: =SUM(D26:D28) -> 22977765 | E29: =SUM(C29:D29) -> 30715365 | I29: 合計 | J29: =SUM(J26:J28) -> 7042080 | K29: =SUM(K26:K28) -> 20209254 | L29: =SUM(J29:K29) -> 27251334
D30: 収入-総原価 | E30: =E29-D4 -> 0.14 | L30: =L29-D4 -> -3464031.4

Sheet 販売量
U1: =ナビ!C4
B2: 販売量情報入力シート
B3: 【販売量設定】
B4: 供給約款のみ* | C4: 0 | D4: Yes=1,No=0
B5: 標準係数を使用* | C5: 0 | D5: Yes=1,No=0
S6: =OFFSET(INDEX(C11:N11, 1, MATCH(MAX(C11:N11), C11:N11, 0)), -4, 0) -> 12
B7: 契約区分 | C7: 1 | D7: 2 | E7: 3 | F7: 4 | G7: 5 | H7: 6 | I7: 7 | J7: 8 | K7: 9 | L7: 10 | M7: 11 | N7: 12 | O7: 合計 | P7: 平均販売量（m3/月・件） | Q7: 需要家数（件/月） | R7: 需要家数（件/年） | S7: ピーク月使用量（m3/月） | T7: メーター能力（m3/台） | U7: 延通過量（m3/年）
B8: 供給約款 | C8: 4620 | D8: 4525 | E8: 4325 | F8: 3725 | G8: 3525 | H8: 3425 | I8: 3425 | J8: 3425 | K8: 3525 | L8: 3825 | M8: 4325 | N8: 5934.4866 | O8: =SUM(C8:N8) -> 48604.487 | P8: =IFERROR(O8/R8,0) -> 8.3858673 | Q8: 483 | R8: =Q8*12 -> 5796 | S8: =OFFSET(INDEX(C11:N11, 1, MATCH(MAX(C11:N11), C11:N11, 0)), -3, 0) -> 5934.4866 | T8: 2.5 | U8: =R8*T8 -> 14490
B9: 非規制需要 | C9: 0 | D9: 0 | E9: 0 | F9: 0 | G9: 0 | H9: 0 | I9: 0 | J9: 0 | K9: 0 | L9: 0 | M9: 0 | N9: 0 | O9: =SUM(C9:N9) -> 0 | P9: =IFERROR(O9/R9,0) -> 0 | Q9: 0 | R9: =Q9*12 -> 0 | S9: =OFFSET(INDEX(C11:N11, 1, MATCH(MAX(C11:N11), C11:N11, 0)), -2, 0) -> 0 | T9: 2.5 | U9: =R9*T9 -> 0
B10: 旧特定大口 | C10: 100.1 | D10: 124 | E10: 42.3 | F10: 24 | G10: 16.5 | H10: 15.2 | I10: 35.6 | J10: 167.1 | K10: 307.5 | L10: 715.4 | M10: 715.3 | N10: 754.4 | O10: =SUM(C10:N10) -> 3017.4 | P10: =IFERROR(O10/R10,0) -> 62.8625 | Q10: 4 | R10: =Q10*12 -> 48 | S10: =OFFSET(INDEX(C11:N11, 1, MATCH(MAX(C11:N11), C11:N11, 0)), -1, 0) -> 754.4 | T10: 2.5 | U10: =R10*T10 -> 120
C11: =SUM(C8:C10) -> 4720.1 | D11: =SUM(D8:D10) -> 4649 | E11: =SUM(E8:E10) -> 4367.3 | F11: =SUM(F8:F10) -> 3749 | G11: =SUM(G8:G10) -> 3541.5 | H11: =SUM(H8:H10) -> 3440.2 | I11: =SUM(I8:I10) -> 3460.6 | J11: =SUM(J8:J10) -> 3592.1 | ... O11: =SUM(O8:O10) -> 51621.887 | P11: =IFERROR(ROUNDDOWN(O11/R11,3),0) -> 8.833 | Q11: =IF(SUM(Q8:Q10)=ナビ!D11,SUM(Q8:Q10),"需要家数相違") -> 487 | R11: =SUM(R8:R10) -> 5844 | S11: =SUM(S8:S10) -> 6688.8866 | U11: =SUM(U8:U10) -> 14610

Sheet 土地
O1: =ナビ!C4
B2: 土地情報入力シート
B4: No. | C4: 所在地等 | D4: 取得年月日 | E4: 取得面積（m2） | F4: 取得価格（円） | G4: 1m2あたり取得価格 | H4: 評価額（円） | I4: 1m2あたり評価額 | J4: 分類ID | K4: 分類名 | L4: 離隔方向 | M4: 所要面積（m2） | N4: 土地投資額 | O4: 土地評価額
B5: 1 | D5: 32153 | E5: 649.1 | F5: 15300000 | G5: =IFERROR(ROUND(F5/E5,0), "") -> 23571 | H5: 6126190 | I5: =IFERROR(ROUND(H5/E5,0), "") -> 9438 | J5: =IF(K5="","",_xlfn.XLOOKUP(K5,標準係数B!T:T,標準係数B!S:S, "IDなし", 0, 1)) -> 11 | K5: ３トン未満_50ｷﾛｸﾞﾗﾑ容器 | L5: 4 | M5: =IFERROR(VLOOKUP(J5,標準係数B!$S$4:$X$20,L5+2,FALSE), "") -> 295 | N5: =IFERROR(IF(E5<=M5,F5,M5*G5),"") -> 6953445 | O5: =IFERROR(IF(E5<=M5,H5,M5*I5),"") -> 2784210
B6: 2 | G6: =IFERROR(ROUND(F6/E6,0), "") | I6: =IFERROR(ROUND(H6/E6,0), "") | J6: =IF(K6="","",_xlfn.XLOOKUP(K6,標準係数B!T:T,標準係数B!S:S, "IDなし", 0, 1)) | M6: =IFERROR(VLOOKUP(J6,標準係数B!$S$4:$X$20,L6+2,FALSE), "") | N6: =IFERROR(IF(E6<=M6,F6,M6*G6),"") -> 0 | O6: =IFERROR(IF(E6<=M6,H6,M6*I6),"") -> 0
B7: 3 | G7: =IFERROR(ROUND(F7/E7,0), "") | I7: =IFERROR(ROUND(H7/E7,0), "") | J7: =IF(K7="","",_xlfn.XLOOKUP(K7,標準係数B!T:T,標準係数B!S:S, "IDなし", 0, 1)) | M7: =IFERROR(VLOOKUP(J7,標準係数B!$S$4:$X$20,L7+2,FALSE), "") | N7: =IFERROR(IF(E7<=M7,F7,M7*G7),"") -> 0 | O7: =IFERROR(IF(E7<=M7,H7,M7*I7),"") -> 0
B8: 4 | G8: =IFERROR(ROUND(F8/E8,0), "") | I8: =IFERROR(ROUND(H8/E8,0), "") | J8: =IF(K8="","",_xlfn.XLOOKUP(K8,標準係数B!T:T,標準係数B!S:S, "IDなし", 0, 1)) | M8: =IFERROR(VLOOKUP(J8,標準係数B!$S$4:$X$20,L8+2,FALSE), "") | N8: =IFERROR(IF(E8<=M8,F8,M8*G8),"") -> 0 | O8: =IFERROR(IF(E8<=M8,H8,M8*I8),"") -> 0
B9: 5 | G9: =IFERROR(ROUND(F9/E9,0), "") | I9: =IFERROR(ROUND(H9/E9,0), "") | J9: =IF(K9="","",_xlfn.XLOOKUP(K9,標準係数B!T:T,標準係数B!S:S, "IDなし", 0, 1)) | M9: =IFERROR(VLOOKUP(J9,標準係数B!$S$4:$X$20,L9+2,FALSE), "") | N9: =IFERROR(IF(E9<=M9,F9,M9*G9),"") -> 0 | O9: =IFERROR(IF(E9<=M9,H9,M9*I9),"") -> 0
B10: 6 | G10: =IFERROR(ROUND(F10/E10,0), "") | I10: =IFERROR(ROUND(H10/E10,0), "") | J10: =IF(K10="","",_xlfn.XLOOKUP(K10,標準係数B!T:T,標準係数B!S:S, "IDなし", 0, 1)) | M10: =IFERROR(VLOOKUP(J10,標準係数B!$S$4:$X$20,L10+2,FALSE), "") | N10: =IFERROR(IF(E10<=M10,F10,M10*G10),"") -> 0 | O10: =IFERROR(IF(E10<=M10,H10,M10*I10),"") -> 0
B11: 7 | G11: =IFERROR(ROUND(F11/E11,0), "") | I11: =IFERROR(ROUND(H11/E11,0), "") | J11: =IF(K11="","",_xlfn.XLOOKUP(K11,標準係数B!T:T,標準係数B!S:S, "IDなし", 0, 1)) | M11: =IFERROR(VLOOKUP(J11,標準係数B!$S$4:$X$20,L11+2,FALSE), "") | N11: =IFERROR(IF(E11<=M11,F11,M11*G11),"") -> 0 | O11: =IFERROR(IF(E11<=M11,H11,M11*I11),"") -> 0
B12: 8 | G12: =IFERROR(ROUND(F12/E12,0), "") | I12: =IFERROR(ROUND(H12/E12,0), "") | J12: =IF(K12="","",_xlfn.XLOOKUP(K12,標準係数B!T:T,標準係数B!S:S, "IDなし", 0, 1)) | M12: =IFERROR(VLOOKUP(J12,標準係数B!$S$4:$X$20,L12+2,FALSE), "") | N12: =IFERROR(IF(E12<=M12,F12,M12*G12),"") -> 0 | O12: =IFERROR(IF(E12<=M12,H12,M12*I12),"") -> 0
B13: 9 | G13: =IFERROR(ROUND(F13/E13,0), "") | I13: =IFERROR(ROUND(H13/E13,0), "") | J13: =IF(K13="","",_xlfn.XLOOKUP(K13,標準係数B!T:T,標準係数B!S:S, "IDなし", 0, 1)) | M13: =IFERROR(VLOOKUP(J13,標準係数B!$S$4:$X$20,L13+2,FALSE), "") | N13: =IFERROR(IF(E13<=M13,F13,M13*G13),"") -> 0 | O13: =IFERROR(IF(E13<=M13,H13,M13*I13),"") -> 0
B14: 10 | G14: =IFERROR(ROUND(F14/E14,0), "") | I14: =IFERROR(ROUND(H14/E14,0), "") | J14: =IF(K14="","",_xlfn.XLOOKUP(K14,標準係数B!T:T,標準係数B!S:S, "IDなし", 0, 1)) | M14: =IFERROR(VLOOKUP(J14,標準係数B!$S$4:$X$20,L14+2,FALSE), "") | N14: =IFERROR(IF(E14<=M14,F14,M14*G14),"") -> 0 | O14: =IFERROR(IF(E14<=M14,H14,M14*I14),"") -> 0
B15: 合計 | E15: =SUM(E5:E14) -> 649.1 | F15: =SUM(F5:F14) -> 15300000 | H15: =SUM(H5:H14) -> 6126190 | M15: =SUM(M5:M14) -> 295 | N15: =SUM(N5:N14) -> 6953445 | O15: =SUM(O5:O14) -> 2784210

Sheet 償却資産
S1: =ナビ!C4
B2: 建物及び償却資産入力シート | H2: =MATCH(償却資産!G6, 標準係数A!B:B, 0) -> 17
I3: 0:非対象 | J3: 0:減免しない | K3: 0:標準係数 | Q3: 修繕費率
I4: 1:対象 | J4: 1:減免する | K4: 1:実績 | Q4: 0.03 | U4: 【期間テーブル】
B5: No. | C5: 項目 | D5: 項目記号 | E5: 供給地点数 | F5: 取得年月日 | G5: 期間ID | H5: 単位投資額 | I5: 減免対象 | J5: 減免サイン | K5: 算出方法 | L5: 実績投資額 | M5: 標準係数 | N5: 投資額基礎 | O5: 投資額① | P5: 投資額② | Q5: 修繕費 | R5: 償却率 | S5: 減価償却費 | U5: 適用開始日 | V5: 期間ID
B6: 1 | C6: 建物 | D6: =IF(C6="","",_xlfn.XLOOKUP(C6,標準係数A!$3:$3,標準係数A!$4:$4, "IDなし", 0, 1)) -> TTM | E6: 141 | F6: 36483 | G6: =IF(F6="","",VLOOKUP(F6,$U$5:$V$24,2,TRUE)) -> HK12 | H6: =IF(C6="","",INDEX(標準係数A!$E:$R, MATCH(償却資産!G6, 標準係数A!B:B, 0), MATCH(償却資産!D6, 標準係数A!$E$4:$R$4, 0))) -> 12670 | I6: =IF(F6="","",IF(AND( F6 <= DATE(2017,4,1), OR(D6="SGS",D6="DKK",D6="DPK",D6="DKT",D6="DPT",D6="SSB")),1,0)) -> 0 | J6: 0 | K6: 0 | M6: =IF(E6="","",E6*H6) -> 1786470 | N6: =IF(E6="","",IF(K6=0,M6,L6)) -> 1786470 | O6: =IF(E6="","",IF(P6=N6,0, N6)) -> 1786470 | P6: =IF(E6="","",IF(AND(I6=1, J6=1), N6, 0)) -> 0 | Q6: =IF(M6="","",ROUND(M6*$Q$4,0)) -> 53594 | R6: =IF(M6="","",HLOOKUP(D6,標準係数A!$E$4:$R$5,2,FALSE)) -> 0.03 | S6: =IF(N6="","",N6*R6) -> 53594.1 | U6: 1 | V6: HK01
B7: 2 | C7: 建物 | D7: =IF(C7="","",_xlfn.XLOOKUP(C7,標準係数A!$3:$3,標準係数A!$4:$4, "IDなし", 0, 1)) -> TTM | E7: 5 | F7: 32599 | G7: =IF(F7="","",VLOOKUP(F7,$U$5:$V$24,2,TRUE)) -> HK11 | H7: =IF(C7="","",INDEX(標準係数A!$E:$R, MATCH(償却資産!G7, 標準係数A!B:B, 0), MATCH(償却資産!D7, 標準係数A!$E$4:$R$4, 0))) -> 10485 | I7: =IF(F7="","",IF(AND( F7 <= DATE(2017,4,1), OR(D7="SGS",D7="DKK",D7="DPK",D7="DKT",D7="DPT",D7="SSB")),1,0)) -> 0 | J7: 0 | K7: 0 | M7: =IF(E7="","",E7*H7) -> 52425 | N7: =IF(E7="","",IF(K7=0,M7,L7)) -> 52425 | O7: =IF(E7="","",IF(P7=N7,0, N7)) -> 52425 | P7: =IF(E7="","",IF(AND(I7=1, J7=1), N7, 0)) -> 0 | Q7: =IF(M7="","",ROUND(M7*$Q$4,0)) -> 1573 | R7: =IF(M7="","",HLOOKUP(D7,標準係数A!$E$4:$R$5,2,FALSE)) -> 0.03 | S7: =IF(N7="","",N7*R7) -> 1572.75 | U7: 26846 | V7: HK02
B8: 3 | C8: 建物 | D8: =IF(C8="","",_xlfn.XLOOKUP(C8,標準係数A!$3:$3,標準係数A!$4:$4, "IDなし", 0, 1)) -> TTM | E8: 341 | F8: 32069 | G8: =IF(F8="","",VLOOKUP(F8,$U$5:$V$24,2,TRUE)) -> HK10 | H8: =IF(C8="","",INDEX(標準係数A!$E:$R, MATCH(償却資産!G8, 標準係数A!B:B, 0), MATCH(償却資産!D8, 標準係数A!$E$4:$R$4, 0))) -> 10350 | I8: =IF(F8="","",IF(AND( F8 <= DATE(2017,4,1), OR(D8="SGS",D8="DKK",D8="DPK",D8="DKT",D8="DPT",D8="SSB")),1,0)) -> 0 | J8: 0 | K8: 0 | M8: =IF(E8="","",E8*H8) -> 3529350 | N8: =IF(E8="","",IF(K8=0,M8,L8)) -> 3529350 | O8: =IF(E8="","",IF(P8=N8,0, N8)) -> 3529350 | P8: =IF(E8="","",IF(AND(I8=1, J8=1), N8, 0)) -> 0 | Q8: =IF(M8="","",ROUND(M8*$Q$4,0)) -> 105881 | R8: =IF(M8="","",HLOOKUP(D8,標準係数A!$E$4:$R$5,2,FALSE)) -> 0.03 | S8: =IF(N8="","",N8*R8) -> 105880.5 | U8: 27292 | V8: HK03
B9: 4 | C9: 構築物 | D9: =IF(C9="","",_xlfn.XLOOKUP(C9,標準係数A!$3:$3,標準係数A!$4:$4, "IDなし", 0, 1)) -> KCB | E9: 141 | F9: 36483 | G9: =IF(F9="","",VLOOKUP(F9,$U$5:$V$24,2,TRUE)) -> HK12 | H9: =IF(C9="","",INDEX(標準係数A!$E:$R, MATCH(償却資産!G9, 標準係数A!B:B, 0), MATCH(償却資産!D9, 標準係数A!$E$4:$R$4, 0))) -> 4960 | I9: =IF(F9="","",IF(AND( F9 <= DATE(2017,4,1), OR(D9="SGS",D9="DKK",D9="DPK",D9="DKT",D9="DPT",D9="SSB")),1,0)) -> 0 | J9: 0 | K9: 0 | M9: =IF(E9="","",E9*H9) -> 699360 | N9: =IF(E9="","",IF(K9=0,M9,L9)) -> 699360 | O9: =IF(E9="","",IF(P9=N9,0, N9)) -> 699360 | P9: =IF(E9="","",IF(AND(I9=1, J9=1), N9, 0)) -> 0 | Q9: =IF(M9="","",ROUND(M9*$Q$4,0)) -> 20981 | R9: =IF(M9="","",HLOOKUP(D9,標準係数A!$E$4:$R$5,2,FALSE)) -> 0.1 | S9: =IF(N9="","",N9*R9) -> 69936 | U9: 27687 | V9: HK04
B10: 5 | C10: 構築物 | D10: =IF(C10="","",_xlfn.XLOOKUP(C10,標準係数A!$3:$3,標準係数A!$4:$4, "IDなし", 0, 1)) -> KCB | E10: 5 | F10: 32599 | G10: =IF(F10="","",VLOOKUP(F10,$U$5:$V$24,2,TRUE)) -> HK11 | H10: =IF(C10="","",INDEX(標準係数A!$E:$R, MATCH(償却資産!G10, 標準係数A!B:B, 0), MATCH(償却資産!D10, 標準係数A!$E$4:$R$4, 0))) -> 1700 | I10: =IF(F10="","",IF(AND( F10 <= DATE(2017,4,1), OR(D10="SGS",D10="DKK",D10="DPK",D10="DKT",D10="DPT",D10="SSB")),1,0)) -> 0 | J10: 0 | K10: 0 | M10: =IF(E10="","",E10*H10) -> 8500 | N10: =IF(E10="","",IF(K10=0,M10,L10)) -> 8500 | O10: =IF(E10="","",IF(P10=N10,0, N10)) -> 8500 | P10: =IF(E10="","",IF(AND(I10=1, J10=1), N10, 0)) -> 0 | Q10: =IF(M10="","",ROUND(M10*$Q$4,0)) -> 255 | R10: =IF(M10="","",HLOOKUP(D10,標準係数A!$E$4:$R$5,2,FALSE)) -> 0.1 | S10: =IF(N10="","",N10*R10) -> 850 | U10: 28135 | V10: HK05
B11: 6 | C11: 構築物 | D11: =IF(C11="","",_xlfn.XLOOKUP(C11,標準係数A!$3:$3,標準係数A!$4:$4, "IDなし", 0, 1)) -> KCB | E11: 341 | F11: 32069 | G11: =IF(F11="","",VLOOKUP(F11,$U$5:$V$24,2,TRUE)) -> HK10 | H11: =IF(C11="","",INDEX(標準係数A!$E:$R, MATCH(償却資産!G11, 標準係数A!B:B, 0), MATCH(償却資産!D11, 標準係数A!$E$4:$R$4, 0))) -> 1680 | I11: =IF(F11="","",IF(AND( F11 <= DATE(2017,4,1), OR(D11="SGS",D11="DKK",D11="DPK",D11="DKT",D11="DPT",D11="SSB")),1,0)) -> 0 | J11: 0 | K11: 0 | M11: =IF(E11="","",E11*H11) -> 572880 | N11: =IF(E11="","",IF(K11=0,M11,L11)) -> 572880 | O11: =IF(E11="","",IF(P11=N11,0, N11)) -> 572880 | P11: =IF(E11="","",IF(AND(I11=1, J11=1), N11, 0)) -> 0 | Q11: =IF(M11="","",ROUND(M11*$Q$4,0)) -> 17186 | R11: =IF(M11="","",HLOOKUP(D11,標準係数A!$E$4:$R$5,2,FALSE)) -> 0.1 | S11: =IF(N11="","",N11*R11) -> 57288 | U11: 28491 | V11: HK06
B12: 7 | C12: 集合装置 | D12: =IF(C12="","",_xlfn.XLOOKUP(C12,標準係数A!$3:$3,標準係数A!$4:$4, "IDなし", 0, 1)) -> SGS | E12: 141 | F12: 36483 | G12: =IF(F12="","",VLOOKUP(F12,$U$5:$V$24,2,TRUE)) -> HK12 | H12: =IF(C12="","",INDEX(標準係数A!$E:$R, MATCH(償却資産!G12, 標準係数A!B:B, 0), MATCH(償却資産!D12, 標準係数A!$E$4:$R$4, 0))) -> 10590 | I12: =IF(F12="","",IF(AND( F12 <= DATE(2017,4,1), OR(D12="SGS",D12="DKK",D12="DPK",D12="DKT",D12="DPT",D12="SSB")),1,0)) -> 1 | J12: 1 | K12: 0 | M12: =IF(E12="","",E12*H12) -> 1493190 | N12: =IF(E12="","",IF(K12=0,M12,L12)) -> 1493190 | O12: =IF(E12="","",IF(P12=N12,0, N12)) -> 0 | P12: =IF(E12="","",IF(AND(I12=1, J12=1), N12, 0)) -> 1493190 | Q12: =IF(M12="","",ROUND(M12*$Q$4,0)) -> 44796 | R12: =IF(M12="","",HLOOKUP(D12,標準係数A!$E$4:$R$5,2,FALSE)) -> 0.1 | S12: =IF(N12="","",N12*R12) -> 149319 | U12: 29188 | V12: HK07
B13: 8 | C13: 集合装置 | D13: =IF(C13="","",_xlfn.XLOOKUP(C13,標準係数A!$3:$3,標準係数A!$4:$4, "IDなし", 0, 1)) -> SGS | E13: 5 | F13: 32599 | G13: =IF(F13="","",VLOOKUP(F13,$U$5:$V$24,2,TRUE)) -> HK11 | H13: =IF(C13="","",INDEX(標準係数A!$E:$R, MATCH(償却資産!G13, 標準係数A!B:B, 0), MATCH(償却資産!D13, 標準係数A!$E$4:$R$4, 0))) -> 6040 | I13: =IF(F13="","",IF(AND( F13 <= DATE(2017,4,1), OR(D13="SGS",D13="DKK",D13="DPK",D13="DKT",D13="DPT",D13="SSB")),1,0)) -> 1 | J13: 1 | K13: 0 | M13: =IF(E13="","",E13*H13) -> 30200 | N13: =IF(E13="","",IF(K13=0,M13,L13)) -> 30200 | O13: =IF(E13="","",IF(P13=N13,0, N13)) -> 0 | P13: =IF(E13="","",IF(AND(I13=1, J13=1), N13, 0)) -> 30200 | Q13: =IF(M13="","",ROUND(M13*$Q$4,0)) -> 906 | R13: =IF(M13="","",HLOOKUP(D13,標準係数A!$E$4:$R$5,2,FALSE)) -> 0.1 | S13: =IF(N13="","",N13*R13) -> 3020 | U13: 29634 | V13: HK08
B14: 9 | C14: 集合装置 | D14: =IF(C14="","",_xlfn.XLOOKUP(C14,標準係数A!$3:$3,標準係数A!$4:$4, "IDなし", 0, 1)) -> SGS | E14: 341 | F14: 32069 | G14: =IF(F14="","",VLOOKUP(F14,$U$5:$V$24,2,TRUE)) -> HK10 | H14: =IF(C14="","",INDEX(標準係数A!$E:$R, MATCH(償却資産!G14, 標準係数A!B:B, 0), MATCH(償却資産!D14, 標準係数A!$E$4:$R$4, 0))) -> 5960 | I14: =IF(F14="","",IF(AND( F14 <= DATE(2017,4,1), OR(D14="SGS",D14="DKK",D14="DPK",D14="DKT",D14="DPT",D14="SSB")),1,0)) -> 1 | J14: 1 | K14: 0 | M14: =IF(E14="","",E14*H14) -> 2032360 | N14: =IF(E14="","",IF(K14=0,M14,L14)) -> 2032360 | O14: =IF(E14="","",IF(P14=N14,0, N14)) -> 0 | P14: =IF(E14="","",IF(AND(I14=1, J14=1), N14, 0)) -> 2032360 | Q14: =IF(M14="","",ROUND(M14*$Q$4,0)) -> 60971 | R14: =IF(M14="","",HLOOKUP(D14,標準係数A!$E$4:$R$5,2,FALSE)) -> 0.1 | S14: =IF(N14="","",N14*R14) -> 203236 | U14: 30545 | V14: HK09
B15: 10 | C15: メーター | D15: =IF(C15="","",_xlfn.XLOOKUP(C15,標準係数A!$3:$3,標準係数A!$4:$4, "IDなし", 0, 1)) -> MTR | E15: 487 | F15: 40424 | G15: =IF(F15="","",VLOOKUP(F15,$U$5:$V$24,2,TRUE)) -> HK15 | H15: =IF(C15="","",INDEX(標準係数A!$E:$R, MATCH(償却資産!G15, 標準係数A!B:B, 0), MATCH(償却資産!D15, 標準係数A!$E$4:$R$4, 0))) -> 11010 | I15: =IF(F15="","",IF(AND( F15 <= DATE(2017,4,1), OR(D15="SGS",D15="DKK",D15="DPK",D15="DKT",D15="DPT",D15="SSB")),1,0)) -> 0 | J15: 0 | K15: 0 | M15: =IF(E15="","",E15*H15) -> 5361870 | N15: =IF(E15="","",IF(K15=0,M15,L15)) -> 5361870 | O15: =IF(E15="","",IF(P15=N15,0, N15)) -> 5361870 | P15: =IF(E15="","",IF(AND(I15=1, J15=1), N15, 0)) -> 0 | Q15: =IF(M15="","",ROUND(M15*$Q$4,0)) -> 160856 | R15: =IF(M15="","",HLOOKUP(D15,標準係数A!$E$4:$R$5,2,FALSE)) -> 0.077 | S15: =IF(N15="","",N15*R15) -> 412863.99 | U15: 32069 | V15: HK10
B16: 11 | C16: 導管・ＰＥ単独 | D16: =IF(C16="","",_xlfn.XLOOKUP(C16,標準係数A!$3:$3,標準係数A!$4:$4, "IDなし", 0, 1)) -> DPT | E16: 141 | F16: 36483 | G16: =IF(F16="","",VLOOKUP(F16,$U$5:$V$24,2,TRUE)) -> HK12 | H16: =IF(C16="","",INDEX(標準係数A!$E:$R, MATCH(償却資産!G16, 標準係数A!B:B, 0), MATCH(償却資産!D16, 標準係数A!$E$4:$R$4, 0))) -> 108630 | I16: =IF(F16="","",IF(AND( F16 <= DATE(2017,4,1), OR(D16="SGS",D16="DKK",D16="DPK",D16="DKT",D16="DPT",D16="SSB")),1,0)) -> 1 | J16: 1 | K16: 0 | M16: =IF(E16="","",E16*H16) -> 15316830 | N16: =IF(E16="","",IF(K16=0,M16,L16)) -> 15316830 | O16: =IF(E16="","",IF(P16=N16,0, N16)) -> 0 | P16: =IF(E16="","",IF(AND(I16=1, J16=1), N16, 0)) -> 15316830 | Q16: =IF(M16="","",ROUND(M16*$Q$4,0)) -> 459505 | R16: =IF(M16="","",HLOOKUP(D16,標準係数A!$E$4:$R$5,2,FALSE)) -> 0.077 | S16: =IF(N16="","",N16*R16) -> 1179395.9 | U16: 32599 | V16: HK11
B17: 12 | C17: 導管・ＰＥ単独 | D17: =IF(C17="","",_xlfn.XLOOKUP(C17,標準係数A!$3:$3,標準係数A!$4:$4, "IDなし", 0, 1)) -> DPT | E17: 5 | F17: 32599 | G17: =IF(F17="","",VLOOKUP(F17,$U$5:$V$24,2,TRUE)) -> HK11 | H17: =IF(C17="","",INDEX(標準係数A!$E:$R, MATCH(償却資産!G17, 標準係数A!B:B, 0), MATCH(償却資産!D17, 標準係数A!$E$4:$R$4, 0))) -> 62930 | I17: =IF(F17="","",IF(AND( F17 <= DATE(2017,4,1), OR(D17="SGS",D17="DKK",D17="DPK",D17="DKT",D17="DPT",D17="SSB")),1,0)) -> 1 | J17: 1 | K17: 0 | M17: =IF(E17="","",E17*H17) -> 314650 | N17: =IF(E17="","",IF(K17=0,M17,L17)) -> 314650 | O17: =IF(E17="","",IF(P17=N17,0, N17)) -> 0 | P17: =IF(E17="","",IF(AND(I17=1, J17=1), N17, 0)) -> 314650 | Q17: =IF(M17="","",ROUND(M17*$Q$4,0)) -> 9440 | R17: =IF(M17="","",HLOOKUP(D17,標準係数A!$E$4:$R$5,2,FALSE)) -> 0.077 | S17: =IF(N17="","",N17*R17) -> 24228.05 | U17: 36483 | V17: HK12
B18: 13 | C18: 導管・ＰＥ単独 | D18: =IF(C18="","",_xlfn.XLOOKUP(C18,標準係数A!$3:$3,標準係数A!$4:$4, "IDなし", 0, 1)) -> DPT | E18: 341 | F18: 32069 | G18: =IF(F18="","",VLOOKUP(F18,$U$5:$V$24,2,TRUE)) -> HK10 | H18: =IF(C18="","",INDEX(標準係数A!$E:$R, MATCH(償却資産!G18, 標準係数A!B:B, 0), MATCH(償却資産!D18, 標準係数A!$E$4:$R$4, 0))) -> 62120 | I18: =IF(F18="","",IF(AND( F18 <= DATE(2017,4,1), OR(D18="SGS",D18="DKK",D18="DPK",D18="DKT",D18="DPT",D18="SSB")),1,0)) -> 1 | J18: 1 | K18: 0 | M18: =IF(E18="","",E18*H18) -> 21182920 | N18: =IF(E18="","",IF(K18=0,M18,L18)) -> 21182920 | O18: =IF(E18="","",IF(P18=N18,0, N18)) -> 0 | P18: =IF(E18="","",IF(AND(I18=1, J18=1), N18, 0)) -> 21182920 | Q18: =IF(M18="","",ROUND(M18*$Q$4,0)) -> 635488 | R18: =IF(M18="","",HLOOKUP(D18,標準係数A!$E$4:$R$5,2,FALSE)) -> 0.077 | S18: =IF(N18="","",N18*R18) -> 1631084.8 | U18: 37987 | V18: HK13
B19: 14 | D19: =IF(C19="","",_xlfn.XLOOKUP(C19,標準係数A!$3:$3,標準係数A!$4:$4, "IDなし", 0, 1)) | G19: =IF(F19="","",VLOOKUP(F19,$U$5:$V$24,2,TRUE)) | H19: =IF(C19="","",INDEX(標準係数A!$E:$R, MATCH(償却資産!G19, 標準係数A!B:B, 0), MATCH(償却資産!D19, 標準係数A!$E$4:$R$4, 0))) | I19: =IF(F19="","",IF(AND( F19 <= DATE(2017,4,1), OR(D19="SGS",D19="DKK",D19="DPK",D19="DKT",D19="DPT",D19="SSB")),1,0)) | M19: =IF(E19="","",E19*H19) | N19: =IF(E19="","",IF(K19=0,M19,L19)) | O19: =IF(E19="","",IF(P19=N19,0, N19)) | P19: =IF(E19="","",IF(AND(I19=1, J19=1), N19, 0)) | Q19: =IF(M19="","",ROUND(M19*$Q$4,0)) | R19: =IF(M19="","",HLOOKUP(D19,標準係数A!$E$4:$R$5,2,FALSE)) | S19: =IF(N19="","",N19*R19) | U19: 39209 | V19: HK14
B20: 15 | D20: =IF(C20="","",_xlfn.XLOOKUP(C20,標準係数A!$3:$3,標準係数A!$4:$4, "IDなし", 0, 1)) | G20: =IF(F20="","",VLOOKUP(F20,$U$5:$V$24,2,TRUE)) | H20: =IF(C20="","",INDEX(標準係数A!$E:$R, MATCH(償却資産!G20, 標準係数A!B:B, 0), MATCH(償却資産!D20, 標準係数A!$E$4:$R$4, 0))) | I20: =IF(F20="","",IF(AND( F20 <= DATE(2017,4,1), OR(D20="SGS",D20="DKK",D20="DPK",D20="DKT",D20="DPT",D20="SSB")),1,0)) | M20: =IF(E20="","",E20*H20) | N20: =IF(E20="","",IF(K20=0,M20,L20)) | O20: =IF(E20="","",IF(P20=N20,0, N20)) | P20: =IF(E20="","",IF(AND(I20=1, J20=1), N20, 0)) | Q20: =IF(M20="","",ROUND(M20*$Q$4,0)) | R20: =IF(M20="","",HLOOKUP(D20,標準係数A!$E$4:$R$5,2,FALSE)) | S20: =IF(N20="","",N20*R20) | U20: 40269 | V20: HK15
B21: 16 | D21: =IF(C21="","",_xlfn.XLOOKUP(C21,標準係数A!$3:$3,標準係数A!$4:$4, "IDなし", 0, 1)) | G21: =IF(F21="","",VLOOKUP(F21,$U$5:$V$24,2,TRUE)) | H21: =IF(C21="","",INDEX(標準係数A!$E:$R, MATCH(償却資産!G21, 標準係数A!B:B, 0), MATCH(償却資産!D21, 標準係数A!$E$4:$R$4, 0))) | I21: =IF(F21="","",IF(AND( F21 <= DATE(2017,4,1), OR(D21="SGS",D21="DKK",D21="DPK",D21="DKT",D21="DPT",D21="SSB")),1,0)) | M21: =IF(E21="","",E21*H21) | N21: =IF(E21="","",IF(K21=0,M21,L21)) | O21: =IF(E21="","",IF(P21=N21,0, N21)) | P21: =IF(E21="","",IF(AND(I21=1, J21=1), N21, 0)) | Q21: =IF(M21="","",ROUND(M21*$Q$4,0)) | R21: =IF(M21="","",HLOOKUP(D21,標準係数A!$E$4:$R$5,2,FALSE)) | S21: =IF(N21="","",N21*R21) | U21: 41365 | V21: HK16
B22: 17 | D22: =IF(C22="","",_xlfn.XLOOKUP(C22,標準係数A!$3:$3,標準係数A!$4:$4, "IDなし", 0, 1)) | G22: =IF(F22="","",VLOOKUP(F22,$U$5:$V$24,2,TRUE)) | H22: =IF(C22="","",INDEX(標準係数A!$E:$R, MATCH(償却資産!G22, 標準係数A!B:B, 0), MATCH(償却資産!D22, 標準係数A!$E$4:$R$4, 0))) | I22: =IF(F22="","",IF(AND( F22 <= DATE(2017,4,1), OR(D22="SGS",D22="DKK",D22="DPK",D22="DKT",D22="DPT",D22="SSB")),1,0)) | M22: =IF(E22="","",E22*H22) | N22: =IF(E22="","",IF(K22=0,M22,L22)) | O22: =IF(E22="","",IF(P22=N22,0, N22)) | P22: =IF(E22="","",IF(AND(I22=1, J22=1), N22, 0)) | Q22: =IF(M22="","",ROUND(M22*$Q$4,0)) | R22: =IF(M22="","",HLOOKUP(D22,標準係数A!$E$4:$R$5,2,FALSE)) | S22: =IF(N22="","",N22*R22) | U22: 42826 | V22: HK17
B23: 18 | D23: =IF(C23="","",_xlfn.XLOOKUP(C23,標準係数A!$3:$3,標準係数A!$4:$4, "IDなし", 0, 1)) | G23: =IF(F23="","",VLOOKUP(F23,$U$5:$V$24,2,TRUE)) | H23: =IF(C23="","",INDEX(標準係数A!$E:$R, MATCH(償却資産!G23, 標準係数A!B:B, 0), MATCH(償却資産!D23, 標準係数A!$E$4:$R$4, 0))) | I23: =IF(F23="","",IF(AND( F23 <= DATE(2017,4,1), OR(D23="SGS",D23="DKK",D23="DPK",D23="DKT",D23="DPT",D23="SSB")),1,0)) | M23: =IF(E23="","",E23*H23) | N23: =IF(E23="","",IF(K23=0,M23,L23)) | O23: =IF(E23="","",IF(P23=N23,0, N23)) | P23: =IF(E23="","",IF(AND(I23=1, J23=1), N23, 0)) | Q23: =IF(M23="","",ROUND(M23*$Q$4,0)) | R23: =IF(M23="","",HLOOKUP(D23,標準係数A!$E$4:$R$5,2,FALSE)) | S23: =IF(N23="","",N23*R23) | U23: 44034 | V23: HK18
B24: 19 | D24: =IF(C24="","",_xlfn.XLOOKUP(C24,標準係数A!$3:$3,標準係数A!$4:$4, "IDなし", 0, 1)) | G24: =IF(F24="","",VLOOKUP(F24,$U$5:$V$24,2,TRUE)) | H24: =IF(C24="","",INDEX(標準係数A!$E:$R, MATCH(償却資産!G24, 標準係数A!B:B, 0), MATCH(償却資産!D24, 標準係数A!$E$4:$R$4, 0))) | I24: =IF(F24="","",IF(AND( F24 <= DATE(2017,4,1), OR(D24="SGS",D24="DKK",D24="DPK",D24="DKT",D24="DPT",D24="SSB")),1,0)) | M24: =IF(E24="","",E24*H24) | N24: =IF(E24="","",IF(K24=0,M24,L24)) | O24: =IF(E24="","",IF(P24=N24,0, N24)) | P24: =IF(E24="","",IF(AND(I24=1, J24=1), N24, 0)) | Q24: =IF(M24="","",ROUND(M24*$Q$4,0)) | R24: =IF(M24="","",HLOOKUP(D24,標準係数A!$E$4:$R$5,2,FALSE)) | S24: =IF(N24="","",N24*R24) | U24: 45169 | V24: HK19
B25: 20 | D25: =IF(C25="","",_xlfn.XLOOKUP(C25,標準係数A!$3:$3,標準係数A!$4:$4, "IDなし", 0, 1)) | G25: =IF(F25="","",VLOOKUP(F25,$U$5:$V$24,2,TRUE)) | H25: =IF(C25="","",INDEX(標準係数A!$E:$R, MATCH(償却資産!G25, 標準係数A!B:B, 0), MATCH(償却資産!D25, 標準係数A!$E$4:$R$4, 0))) | I25: =IF(F25="","",IF(AND( F25 <= DATE(2017,4,1), OR(D25="SGS",D25="DKK",D25="DPK",D25="DKT",D25="DPT",D25="SSB")),1,0)) | M25: =IF(E25="","",E25*H25) | N25: =IF(E25="","",IF(K25=0,M25,L25)) | O25: =IF(E25="","",IF(P25=N25,0, N25)) | P25: =IF(E25="","",IF(AND(I25=1, J25=1), N25, 0)) | Q25: =IF(M25="","",ROUND(M25*$Q$4,0)) | R25: =IF(M25="","",HLOOKUP(D25,標準係数A!$E$4:$R$5,2,FALSE)) | S25: =IF(N25="","",N25*R25)
B26: 21 | D26: =IF(C26="","",_xlfn.XLOOKUP(C26,標準係数A!$3:$3,標準係数A!$4:$4, "IDなし", 0, 1)) | G26: =IF(F26="","",VLOOKUP(F26,$U$5:$V$24,2,TRUE)) | H26: =IF(C26="","",INDEX(標準係数A!$E:$R, MATCH(償却資産!G26, 標準係数A!B:B, 0), MATCH(償却資産!D26, 標準係数A!$E$4:$R$4, 0))) | I26: =IF(F26="","",IF(AND( F26 <= DATE(2017,4,1), OR(D26="SGS",D26="DKK",D26="DPK",D26="DKT",D26="DPT",D26="SSB")),1,0)) | M26: =IF(E26="","",E26*H26) | N26: =IF(E26="","",IF(K26=0,M26,L26)) | O26: =IF(E26="","",IF(P26=N26,0, N26)) | P26: =IF(E26="","",IF(AND(I26=1, J26=1), N26, 0)) | Q26: =IF(M26="","",ROUND(M26*$Q$4,0)) | R26: =IF(M26="","",HLOOKUP(D26,標準係数A!$E$4:$R$5,2,FALSE)) | S26: =IF(N26="","",N26*R26)
B27: 22 | D27: =IF(C27="","",_xlfn.XLOOKUP(C27,標準係数A!$3:$3,標準係数A!$4:$4, "IDなし", 0, 1)) | G27: =IF(F27="","",VLOOKUP(F27,$U$5:$V$24,2,TRUE)) | H27: =IF(C27="","",INDEX(標準係数A!$E:$R, MATCH(償却資産!G27, 標準係数A!B:B, 0), MATCH(償却資産!D27, 標準係数A!$E$4:$R$4, 0))) | I27: =IF(F27="","",IF(AND( F27 <= DATE(2017,4,1), OR(D27="SGS",D27="DKK",D27="DPK",D27="DKT",D27="DPT",D27="SSB")),1,0)) | M27: =IF(E27="","",E27*H27) | N27: =IF(E27="","",IF(K27=0,M27,L27)) | O27: =IF(E27="","",IF(P27=N27,0, N27)) | P27: =IF(E27="","",IF(AND(I27=1, J27=1), N27, 0)) | Q27: =IF(M27="","",ROUND(M27*$Q$4,0)) | R27: =IF(M27="","",HLOOKUP(D27,標準係数A!$E$4:$R$5,2,FALSE)) | S27: =IF(N27="","",N27*R27)
B28: 23 | D28: =IF(C28="","",_xlfn.XLOOKUP(C28,標準係数A!$3:$3,標準係数A!$4:$4, "IDなし", 0, 1)) | G28: =IF(F28="","",VLOOKUP(F28,$U$5:$V$24,2,TRUE)) | H28: =IF(C28="","",INDEX(標準係数A!$E:$R, MATCH(償却資産!G28, 標準係数A!B:B, 0), MATCH(償却資産!D28, 標準係数A!$E$4:$R$4, 0))) | I28: =IF(F28="","",IF(AND( F28 <= DATE(2017,4,1), OR(D28="SGS",D28="DKK",D28="DPK",D28="DKT",D28="DPT",D28="SSB")),1,0)) | M28: =IF(E28="","",E28*H28) | N28: =IF(E28="","",IF(K28=0,M28,L28)) | O28: =IF(E28="","",IF(P28=N28,0, N28)) | P28: =IF(E28="","",IF(AND(I28=1, J28=1), N28, 0)) | Q28: =IF(M28="","",ROUND(M28*$Q$4,0)) | R28: =IF(M28="","",HLOOKUP(D28,標準係数A!$E$4:$R$5,2,FALSE)) | S28: =IF(N28="","",N28*R28)
B29: 24 | D29: =IF(C29="","",_xlfn.XLOOKUP(C29,標準係数A!$3:$3,標準係数A!$4:$4, "IDなし", 0, 1)) | G29: =IF(F29="","",VLOOKUP(F29,$U$5:$V$24,2,TRUE)) | H29: =IF(C29="","",INDEX(標準係数A!$E:$R, MATCH(償却資産!G29, 標準係数A!B:B, 0), MATCH(償却資産!D29, 標準係数A!$E$4:$R$4, 0))) | I29: =IF(F29="","",IF(AND( F29 <= DATE(2017,4,1), OR(D29="SGS",D29="DKK",D29="DPK",D29="DKT",D29="DPT",D29="SSB")),1,0)) | M29: =IF(E29="","",E29*H29) | N29: =IF(E29="","",IF(K29=0,M29,L29)) | O29: =IF(E29="","",IF(P29=N29,0, N29)) | P29: =IF(E29="","",IF(AND(I29=1, J29=1), N29, 0)) | Q29: =IF(M29="","",ROUND(M29*$Q$4,0)) | R29: =IF(M29="","",HLOOKUP(D29,標準係数A!$E$4:$R$5,2,FALSE)) | S29: =IF(N29="","",N29*R29)
B30: 25 | D30: =IF(C30="","",_xlfn.XLOOKUP(C30,標準係数A!$3:$3,標準係数A!$4:$4, "IDなし", 0, 1)) | G30: =IF(F30="","",VLOOKUP(F30,$U$5:$V$24,2,TRUE)) | H30: =IF(C30="","",INDEX(標準係数A!$E:$R, MATCH(償却資産!G30, 標準係数A!B:B, 0), MATCH(償却資産!D30, 標準係数A!$E$4:$R$4, 0))) | I30: =IF(F30="","",IF(AND( F30 <= DATE(2017,4,1), OR(D30="SGS",D30="DKK",D30="DPK",D30="DKT",D30="DPT",D30="SSB")),1,0)) | M30: =IF(E30="","",E30*H30) | N30: =IF(E30="","",IF(K30=0,M30,L30)) | O30: =IF(E30="","",IF(P30=N30,0, N30)) | P30: =IF(E30="","",IF(AND(I30=1, J30=1), N30, 0)) | Q30: =IF(M30="","",ROUND(M30*$Q$4,0)) | R30: =IF(M30="","",HLOOKUP(D30,標準係数A!$E$4:$R$5,2,FALSE)) | S30: =IF(N30="","",N30*R30)
B31: 26 | D31: =IF(C31="","",_xlfn.XLOOKUP(C31,標準係数A!$3:$3,標準係数A!$4:$4, "IDなし", 0, 1)) | G31: =IF(F31="","",VLOOKUP(F31,$U$5:$V$24,2,TRUE)) | H31: =IF(C31="","",INDEX(標準係数A!$E:$R, MATCH(償却資産!G31, 標準係数A!B:B, 0), MATCH(償却資産!D31, 標準係数A!$E$4:$R$4, 0))) | I31: =IF(F31="","",IF(AND( F31 <= DATE(2017,4,1), OR(D31="SGS",D31="DKK",D31="DPK",D31="DKT",D31="DPT",D31="SSB")),1,0)) | M31: =IF(E31="","",E31*H31) | N31: =IF(E31="","",IF(K31=0,M31,L31)) | O31: =IF(E31="","",IF(P31=N31,0, N31)) | P31: =IF(E31="","",IF(AND(I31=1, J31=1), N31, 0)) | Q31: =IF(M31="","",ROUND(M31*$Q$4,0)) | R31: =IF(M31="","",HLOOKUP(D31,標準係数A!$E$4:$R$5,2,FALSE)) | S31: =IF(N31="","",N31*R31)
B32: 27 | D32: =IF(C32="","",_xlfn.XLOOKUP(C32,標準係数A!$3:$3,標準係数A!$4:$4, "IDなし", 0, 1)) | G32: =IF(F32="","",VLOOKUP(F32,$U$5:$V$24,2,TRUE)) | H32: =IF(C32="","",INDEX(標準係数A!$E:$R, MATCH(償却資産!G32, 標準係数A!B:B, 0), MATCH(償却資産!D32, 標準係数A!$E$4:$R$4, 0))) | I32: =IF(F32="","",IF(AND( F32 <= DATE(2017,4,1), OR(D32="SGS",D32="DKK",D32="DPK",D32="DKT",D32="DPT",D32="SSB")),1,0)) | M32: =IF(E32="","",E32*H32) | N32: =IF(E32="","",IF(K32=0,M32,L32)) | O32: =IF(E32="","",IF(P32=N32,0, N32)) | P32: =IF(E32="","",IF(AND(I32=1, J32=1), N32, 0)) | Q32: =IF(M32="","",ROUND(M32*$Q$4,0)) | R32: =IF(M32="","",HLOOKUP(D32,標準係数A!$E$4:$R$5,2,FALSE)) | S32: =IF(N32="","",N32*R32)
B33: 28 | D33: =IF(C33="","",_xlfn.XLOOKUP(C33,標準係数A!$3:$3,標準係数A!$4:$4, "IDなし", 0, 1)) | G33: =IF(F33="","",VLOOKUP(F33,$U$5:$V$24,2,TRUE)) | H33: =IF(C33="","",INDEX(標準係数A!$E:$R, MATCH(償却資産!G33, 標準係数A!B:B, 0), MATCH(償却資産!D33, 標準係数A!$E$4:$R$4, 0))) | I33: =IF(F33="","",IF(AND( F33 <= DATE(2017,4,1), OR(D33="SGS",D33="DKK",D33="DPK",D33="DKT",D33="DPT",D33="SSB")),1,0)) | M33: =IF(E33="","",E33*H33) | N33: =IF(E33="","",IF(K33=0,M33,L33)) | O33: =IF(E33="","",IF(P33=N33,0, N33)) | P33: =IF(E33="","",IF(AND(I33=1, J33=1), N33, 0)) | Q33: =IF(M33="","",ROUND(M33*$Q$4,0)) | R33: =IF(M33="","",HLOOKUP(D33,標準係数A!$E$4:$R$5,2,FALSE)) | S33: =IF(N33="","",N33*R33)
B34: 29 | D34: =IF(C34="","",_xlfn.XLOOKUP(C34,標準係数A!$3:$3,標準係数A!$4:$4, "IDなし", 0, 1)) | G34: =IF(F34="","",VLOOKUP(F34,$U$5:$V$24,2,TRUE)) | H34: =IF(C34="","",INDEX(標準係数A!$E:$R, MATCH(償却資産!G34, 標準係数A!B:B, 0), MATCH(償却資産!D34, 標準係数A!$E$4:$R$4, 0))) | I34: =IF(F34="","",IF(AND( F34 <= DATE(2017,4,1), OR(D34="SGS",D34="DKK",D34="DPK",D34="DKT",D34="DPT",D34="SSB")),1,0)) | M34: =IF(E34="","",E34*H34) | N34: =IF(E34="","",IF(K34=0,M34,L34)) | O34: =IF(E34="","",IF(P34=N34,0, N34)) | P34: =IF(E34="","",IF(AND(I34=1, J34=1), N34, 0)) | Q34: =IF(M34="","",ROUND(M34*$Q$4,0)) | R34: =IF(M34="","",HLOOKUP(D34,標準係数A!$E$4:$R$5,2,FALSE)) | S34: =IF(N34="","",N34*R34)
B35: 30 | D35: =IF(C35="","",_xlfn.XLOOKUP(C35,標準係数A!$3:$3,標準係数A!$4:$4, "IDなし", 0, 1)) | G35: =IF(F35="","",VLOOKUP(F35,$U$5:$V$24,2,TRUE)) | H35: =IF(C35="","",INDEX(標準係数A!$E:$R, MATCH(償却資産!G35, 標準係数A!B:B, 0), MATCH(償却資産!D35, 標準係数A!$E$4:$R$4, 0))) | I35: =IF(F35="","",IF(AND( F35 <= DATE(2017,4,1), OR(D35="SGS",D35="DKK",D35="DPK",D35="DKT",D35="DPT",D35="SSB")),1,0)) | M35: =IF(E35="","",E35*H35) | N35: =IF(E35="","",IF(K35=0,M35,L35)) | O35: =IF(E35="","",IF(P35=N35,0, N35)) | P35: =IF(E35="","",IF(AND(I35=1, J35=1), N35, 0)) | Q35: =IF(M35="","",ROUND(M35*$Q$4,0)) | R35: =IF(M35="","",HLOOKUP(D35,標準係数A!$E$4:$R$5,2,FALSE)) | S35: =IF(N35="","",N35*R35)
B36: 31 | D36: =IF(C36="","",_xlfn.XLOOKUP(C36,標準係数A!$3:$3,標準係数A!$4:$4, "IDなし", 0, 1)) | G36: =IF(F36="","",VLOOKUP(F36,$U$5:$V$24,2,TRUE)) | H36: =IF(C36="","",INDEX(標準係数A!$E:$R, MATCH(償却資産!G36, 標準係数A!B:B, 0), MATCH(償却資産!D36, 標準係数A!$E$4:$R$4, 0))) | I36: =IF(F36="","",IF(AND( F36 <= DATE(2017,4,1), OR(D36="SGS",D36="DKK",D36="DPK",D36="DKT",D36="DPT",D36="SSB")),1,0)) | M36: =IF(E36="","",E36*H36) | N36: =IF(E36="","",IF(K36=0,M36,L36)) | O36: =IF(E36="","",IF(P36=N36,0, N36)) | P36: =IF(E36="","",IF(AND(I36=1, J36=1), N36, 0)) | Q36: =IF(M36="","",ROUND(M36*$Q$4,0)) | R36: =IF(M36="","",HLOOKUP(D36,標準係数A!$E$4:$R$5,2,FALSE)) | S36: =IF(N36="","",N36*R36)
... B55: 50 | D55: =IF(C55="","",_xlfn.XLOOKUP(C55,標準係数A!$3:$3,標準係数A!$4:$4, "IDなし", 0, 1)) | G55: =IF(F55="","",VLOOKUP(F55,$U$5:$V$24,2,TRUE)) | H55: =IF(C55="","",INDEX(標準係数A!$E:$R, MATCH(償却資産!G55, 標準係数A!B:B, 0), MATCH(償却資産!D55, 標準係数A!$E$4:$R$4, 0))) | I55: =IF(F55="","",IF(AND( F55 <= DATE(2017,4,1), OR(D55="SGS",D55="DKK",D55="DPK",D55="DKT",D55="DPT",D55="SSB")),1,0)) | M55: =IF(E55="","",E55*H55) | N55: =IF(E55="","",IF(K55=0,M55,L55)) | O55: =IF(E55="","",IF(P55=N55,0, N55)) | P55: =IF(E55="","",IF(AND(I55=1, J55=1), N55, 0)) | Q55: =IF(M55="","",ROUND(M55*$Q$4,0)) | R55: =IF(M55="","",HLOOKUP(D55,標準係数A!$E$4:$R$5,2,FALSE)) | S55: =IF(N55="","",N55*R55)
B56: 合計 | C56: - | D56: - | E56: - | F56: - | G56: - | H56: - | I56: - | J56: - | L56: =SUM(L6:L55) -> 0 | M56: =SUM(M6:M55) -> 52381005 | N56: =SUM(N6:N55) -> 52381005 | O56: =SUM(O6:O55) -> 12010855 | P56: =SUM(P6:P55) -> 40370150 | Q56: =SUM(Q6:Q55) -> 1571432 | R56: - | S56: =SUM(S6:S55) -> 3892269.1
B58: 【項目別集計】 | I58: 【チェックリスト】
B59: 集計科目 | C59: 項目記号 | D59: 地点数 | E59: 投資額① | F59: 投資額② | G59: 合計 | I59: FALSE | J59: 建物
...

Sheet 車両
K1: =ナビ!C4
B2: １供給地点当たりの車両の標準投資額
B4: 取得時期 | D4: =IF(C4="","",VLOOKUP(C4,償却資産!U6:V24,2,TRUE)) | E4: …車両標準係数の抽出
C5: 供給70地点以上・250地点まで | D5: 供給250地点以上・1000地点まで | E5: 供給1000地点以上・2000地点まで | F5: 供給2000地点以上・3000地点まで | G5: 供給3000地点以上・4000地点まで | H5: 供給4000地点以上・5000地点まで | I5: 供給5000地点以上・6000地点まで | J5: 供給6001地点以上 | K5: 合計
B6: 地点数区分 | C6: CA1 | D6: CA2 | E6: CA3 | F6: CA4 | G6: CA5 | H6: CA6 | I6: CA7 | J6: CA8
B7: 該当係数 | C7: =IF(C4="","",INDEX(標準係数A!$A:$AA, MATCH($D$4,標準係数A!$B:$B, 0), MATCH(C6, 標準係数A!$4:$4, 0))) | D7: =IF(C4="","",INDEX(標準係数A!$A:$AA, MATCH($D$4,標準係数A!$B:$B, 0), MATCH(D6, 標準係数A!$4:$4, 0))) | E7: =IF(C4="","",INDEX(標準係数A!$A:$AA, MATCH($D$4,標準係数A!$B:$B, 0), MATCH(E6, 標準係数A!$4:$4, 0))) | F7: =IF(C4="","",INDEX(標準係数A!$A:$AA, MATCH($D$4,標準係数A!$B:$B, 0), MATCH(F6, 標準係数A!$4:$4, 0))) | G7: =IF(C4="","",INDEX(標準係数A!$A:$AA, MATCH($D$4,標準係数A!$B:$B, 0), MATCH(G6, 標準係数A!$4:$4, 0))) | H7: =IF(C4="","",INDEX(標準係数A!$A:$AA, MATCH($D$4,標準係数A!$B:$B, 0), MATCH(H6, 標準係数A!$4:$4, 0))) | I7: =IF(C4="","",INDEX(標準係数A!$A:$AA, MATCH($D$4,標準係数A!$B:$B, 0), MATCH(I6, 標準係数A!$4:$4, 0))) | J7: =IF(C4="","",INDEX(標準係数A!$A:$AA, MATCH($D$4,標準係数A!$B:$B, 0), MATCH(J6, 標準係数A!$4:$4, 0)))
B8: 最大値 | C8: 250 | D8: 1000 | E8: 2000 | F8: 3000 | G8: 4000 | H8: 5000 | I8: 6000 | J8: 999999
B9: 対象地点数 | C9: =MIN(ナビ!$D$11, C8) -> 250 | D9: =MAX(0, MIN(D8-C8, ナビ!$D$11-C8)) -> 237 | E9: =MAX(0, MIN(E8-D8, ナビ!$D$11-D8)) -> 0 | F9: =MAX(0, MIN(F8-E8, ナビ!$D$11-E8)) -> 0 | G9: =MAX(0, MIN(G8-F8, ナビ!$D$11-F8)) -> 0 | H9: =MAX(0, MIN(H8-G8, ナビ!$D$11-G8)) -> 0 | I9: =MAX(0, MIN(I8-H8, ナビ!$D$11-H8)) -> 0 | J9: =MAX(0, MIN(J8-I8, ナビ!$D$11-I8)) -> 0
B10: 投資額 | C10: =IFERROR(C7*C9,0) -> 0 | D10: =IFERROR(D7*D9,0) -> 0 | E10: =IFERROR(E7*E9,0) -> 0 | F10: =IFERROR(F7*F9,0) -> 0 | G10: =IFERROR(G7*G9,0) -> 0 | H10: =IFERROR(H7*H9,0) -> 0 | I10: =IFERROR(I7*I9,0) -> 0 | J10: =IFERROR(J7*J9,0) -> 0 | K10: =SUM(C10:J10) -> 0
J11: 修繕費率 | K11: =標準係数B!K6 -> 0.03
J12: 修繕費 | K12: =ROUND(K10*K11,0) -> 0

Sheet 道路占用料
E1: =ナビ!C4
B2: 道路占用料
B4: 道路占用料の区分 | D4: 甲地
C5: 地点数 | D5: 単価 | E5: 占用料
B6: 共同住宅 | C6: =ナビ!D12 -> 0 | D6: =VLOOKUP(D4,標準係数B!$AA$4:$AC$6,3,FALSE) -> 190 | E6: =C6*D6 -> 0
B7: 単独住宅 | C7: =ナビ!D13 -> 487 | D7: =VLOOKUP(D4,標準係数B!$AA$4:$AC$6,2,FALSE) -> 700 | E7: =C7*D7 -> 340900
B8: 合計 | E8: =SUM(E6:E7) -> 340900

Sheet 標準係数A
B2: １供給地点当たり建物及び償却資産投資額の標準投資額 | T2: １供給地点当たりの車両の標準投資額
B3: 期間ID | C3: 適用開始 | D3: 適用終了 | E3: 建物 | F3: 構築物 | G3: 集合装置 | H3: 容器 | I3: 導管・鋼管共同 | J3: 導管・ＰＥ共同 | K3: 導管・鋼管単独 | L3: 導管・ＰＥ単独 | M3: メーター | N3: 備品 | O3: 構築物・バルク | P3: 集合装置・バルク | Q3: 容器・バルク | R3: 強制気化装置 | T3: 供給70地点以上・250地点まで | U3: 供給250地点以上・1000地点まで | V3: 供給1000地点以上・2000地点まで | W3: 供給2000地点以上・3000地点まで | X3: 供給3000地点以上・4000地点まで | Y3: 供給4000地点以上・5000地点まで | Z3: 供給5000地点以上・6000地点まで | AA3: 供給6001地点以上
C4: 項目記号 | E4: TTM | F4: KCB | G4: SGS | H4: YKI | I4: DKK | J4: DPK | K4: DKT | L4: DPT | M4: MTR | N4: BHN | O4: KBB | P4: SSB | Q4: YKB | R4: KKS | T4: CA1 | U4: CA2 | V4: CA3 | W4: CA4 | X4: CA5 | Y4: CA6 | Z4: CA7 | AA4: CA8
B5: 償却率 | E5: 0.03 | F5: 0.1 | G5: 0.1 | H5: 0.167 | I5: 0.077 | J5: 0.077 | K5: 0.077 | L5: 0.077 | M5: 0.077 | N5: 0.2 | O5: 0.1 | P5: 0.1 | Q5: 0.167 | R5: 0.1
B6: HK01 | C6: 1 | D6: 26845 | E6: 2910 | G6: 2080 | H6: 2640 | I6: 3080 | K6: 14080 | M6: 2530 | N6: 160 | O6: 0 | P6: 0 | Q6: 0
B7: HK02 | C7: 26846 | D7: 27291 | E7: 3400 | F7: 550 | G7: 2080 | H7: 3450 | I7: 6790 | K7: 22390 | M7: 2970 | N7: 160 | O7: 0 | P7: 0 | Q7: 0
B8: HK03 | C8: 27292 | D8: 27686 | E8: 6040 | F8: 950 | G8: 2780 | H8: 4910 | I8: 8440 | K8: 27730 | M8: 4570 | N8: 190 | O8: 0 | P8: 0 | Q8: 0
B9: HK04 | C9: 27687 | D9: 28134 | E9: 5840 | F9: 960 | G9: 3680 | H9: 4490 | I9: 9740 | K9: 32540 | M9: 4790 | N9: 270 | O9: 0 | P9: 0 | Q9: 0
B10: HK05 | C10: 28135 | D10: 28490 | E10: 7150 | F10: 1020 | G10: 3920 | H10: 5450 | I10: 11270 | K10: 37610 | M10: 5090 | N10: 280 | O10: 0 | P10: 0 | Q10: 0
B11: HK06 | C11: 28491 | D11: 29187 | E11: 7550 | F11: 1250 | G11: 4160 | H11: 5710 | I11: 11850 | K11: 38690 | M11: 5120 | N11: 300 | O11: 0 | P11: 0 | Q11: 0
B12: HK07 | C12: 29188 | D12: 29633 | E12: 7870 | F12: 1300 | G12: 4310 | H12: 5740 | I12: 12260 | K12: 40150 | M12: 5390 | N12: 310 | O12: 0 | P12: 0 | Q12: 0
B13: HK08 | C13: 29634 | D13: 30544 | E13: 8770 | F13: 1450 | G13: 4800 | H13: 6400 | I13: 13660 | K13: 44730 | M13: 6010 | N13: 350 | O13: 0 | P13: 0 | Q13: 0
B14: HK09 | C14: 30545 | D14: 32068 | E14: 9380 | F14: 1550 | G14: 5130 | H14: 6840 | I14: 14610 | K14: 47820 | M14: 6430 | N14: 380 | O14: 0 | P14: 0 | Q14: 0 | T14: 4440 | U14: 2610 | V14: 1940 | W14: 1740 | X14: 1650 | Y14: 1610 | Z14: 1580 | AA14: 1570
B15: HK10 | C15: 32069 | D15: 32598 | E15: 10350 | F15: 1680 | G15: 5960 | H15: 5810 | I15: 15730 | J15: 19600 | K15: 53160 | L15: 62120 | M15: 5500 | N15: 300 | O15: 0 | P15: 0 | Q15: 0 | T15: 4980 | U15: 2230 | V15: 1600 | W15: 1575 | X15: 1565 | Y15: 1550 | Z15: 1540 | AA15: 1530
B16: HK11 | C16: 32599 | D16: 36482 | E16: 10485 | F16: 1700 | G16: 6040 | H16: 5885 | I16: 15935 | J16: 19855 | K16: 53850 | L16: 62930 | M16: 5570 | N16: 305 | O16: 0 | P16: 0 | Q16: 0 | T16: 4880 | U16: 2190 | V16: 1565 | W16: 1540 | X16: 1530 | Y16: 1520 | Z16: 1505 | AA16: 1495
B17: HK12 | C17: 36483 | D17: 37986 | E17: 12670 | F17: 4960 | G17: 10590 | H17: 5270 | I17: 26170 | J17: 32810 | K17: 88660 | L17: 108630 | M17: 14290 | N17: 390 | O17: 0 | P17: 0 | Q17: 0 | T17: 7250 | U17: 5330 | V17: 4450 | W17: 4140 | X17: 4000 | Y17: 3910 | Z17: 3700 | AA17: 3560
B18: HK13 | C18: 37987 | D18: 39208 | E18: 11520 | F18: 4430 | G18: 10560 | H18: 4560 | I18: 30570 | J18: 32380 | K18: 98230 | L18: 105990 | M18: 13940 | N18: 810 | O18: 0 | P18: 0 | Q18: 0 | T18: 7270 | U18: 5450 | V18: 4540 | W18: 4240 | X18: 4090 | Y18: 4000 | Z18: 3790 | AA18: 3640
B19: HK14 | C19: 39209 | D19: 40268 | E19: 12350 | F19: 4230 | G19: 10980 | H19: 4320 | I19: 33270 | J19: 32080 | K19: 108160 | L19: 103690 | M19: 13020 | N19: 390 | O19: 32410 | P19: 12350 | Q19: 8400 | T19: 7900 | U19: 5930 | V19: 4940 | W19: 4610 | X19: 4440 | Y19: 4340 | Z19: 4110 | AA19: 3950
B20: HK15 | C20: 40269 | D20: 41364 | E20: 9100 | F20: 3660 | G20: 10460 | H20: 2990 | I20: 35440 | J20: 32280 | K20: 114430 | L20: 104610 | M20: 11010 | N20: 380 | O20: 17390 | P20: 13610 | Q20: 9670 | R20: 18520 | T20: 8240 | U20: 6180 | V20: 5150 | W20: 4810 | X20: 4640 | Y20: 4530 | Z20: 4290 | AA20: 4120
B21: HK16 | C21: 41365 | D21: 42825 | E21: 9060 | F21: 4360 | G21: 9620 | H21: 2910 | I21: 36340 | J21: 32250 | K21: 116810 | L21: 103950 | M21: 9950 | N21: 320 | O21: 17170 | P21: 11740 | Q21: 8950 | R21: 19580 | T21: 8310 | U21: 6230 | V21: 5190 | W21: 4850 | X21: 4670 | Y21: 4570 | Z21: 4330 | AA21: 4150
B22: HK17 | C22: 42826 | D22: 44033 | E22: 10950 | F22: 4930 | G22: 10070 | H22: 2790 | I22: 40820 | J22: 35620 | K22: 132770 | L22: 117540 | M22: 9650 | N22: 340 | O22: 19670 | P22: 11500 | Q22: 8900 | R22: 20400 | T22: 8560 | U22: 6420 | V22: 5350 | W22: 4990 | X22: 4810 | Y22: 4700 | Z22: 4450 | AA22: 4280
B23: HK18 | C23: 44034 | D23: 45168 | E23: 11910 | F23: 5030 | G23: 10660 | H23: 3010 | I23: 40820 | J23: 35620 | K23: 132770 | L23: 123680 | M23: 9720 | N23: 380 | O23: 20590 | P23: 12180 | Q23: 9000 | R23: 20780 | T23: 8910 | U23: 6680 | V23: 5570 | W23: 5200 | X23: 5010 | Y23: 4900 | Z23: 4640 | AA23: 4450
